[META]
version=2.0
spawnOnBlockType=2,3
spawnSunlight=True
spawnDarkness=True
spawnWater=False
spawnLava=False
underFill=False
randomRotation=True
dig=True
tree=True
branch=False
needsFoundation=True
rarity=100
collisionPercentage=20
spawnElevationMin=0
spawnElevationMax=200
spawnInBiome=Custom
[DATA]
0,0,-3:162.12
0,0,-2:162.12
0,0,-1:162.12
1,0,-1:162.12
-1,1,-1:162.12
0,1,-1:162.12
0,1,1:161.12
-1,0,2:161.12
-1,1,2:161.12
1,1,2:161.12
0,-3,3:161.12
-2,-2,3:161.12
1,-2,3:161.12
2,-2,3:161.12
-3,-1,3:161.12
-1,-1,3:161.12
0,-1,3:161.12
3,-1,3:161.12
-2,0,3:161.12
-1,0,3:161.12
2,0,3:161.12
-3,1,3:161.12
-1,1,3:161.12
0,1,3:161.12
-2,2,3:161.12
0,2,3:161.12
2,2,3:161.12
2,3,3:161.12
-2,-2,4:161.12
0,-2,4:161.12
-2,-1,4:161.12
-1,-1,4:161.12
0,-1,4:161.12
1,-1,4:161.12
2,-1,4:161.12
-3,0,4:161.12
-2,0,4:161.12
-1,0,4:161.12
1,0,4:161.12
-3,1,4:161.12
-1,1,4:161.12
0,1,4:161.12
2,1,4:161.12
-3,2,4:161.12
-2,2,4:161.12
-1,2,4:161.12
1,2,4:161.12
2,2,4:161.12
0,3,4:161.12
0,-2,5:161.12
-1,-1,5:161.12
2,-1,5:161.12
2,0,5:161.12
-3,1,5:161.12
-2,1,5:161.12
-1,1,5:161.12
1,1,5:161.12
3,1,5:161.12
-2,2,5:161.12
1,2,5:161.12
2,2,5:161.12
-1,-3,6:161.12
1,-3,6:161.12
0,-2,6:161.12
1,-2,6:161.12
-3,-1,6:161.12
-2,-1,6:161.12
-1,-1,6:161.12
0,-1,6:161.12
1,-1,6:161.12
2,-1,6:161.12
-1,0,6:161.12
0,0,6:161.12
3,0,6:18.6
1,1,6:161.12
-2,-1,7:161.12
0,-1,7:161.12
-2,0,7:161.12
-1,0,7:161.12
0,0,7:161.12
2,1,7:161.12
-1,-2,8:161.12
1,-2,8:161.12
-1,-1,8:161.12
0,-1,8:161.12
2,-1,8:18.6
1,0,8:161.12
1,1,7:162.12
1,0,7:162.12
1,-1,7:162.12
-1,-1,7:162.12
0,1,6:162.12
2,0,6:162.12
1,0,6:162.12
2,1,5:162.12
0,1,5:162.12
1,0,5:162.12
0,0,5:162.12
-1,0,5:162.12
1,-1,5:162.12
0,-1,5:162.12
-2,-1,5:162.12
1,-2,5:162.12
-1,-2,5:162.12
0,2,4:162.12
1,1,4:162.12
-2,1,4:162.12
0,0,4:162.12
1,2,3:162.12
-1,2,3:162.12
1,1,3:162.12
1,0,3:162.12
0,0,3:162.12
2,-1,3:162.12
1,-1,3:162.12
-2,-1,3:162.12
0,-2,3:162.12
2,2,2:162.12
0,2,2:162.12
0,1,2:162.12
1,0,2:162.12
0,0,2:162.12
-1,-1,2:162.12
-2,-1,2:162.12
0,-2,2:162.12
0,2,1:162.12
1,1,1:162.12
-1,1,1:162.12
0,0,1:162.12
-1,0,1:162.12
0,-2,1:162.12
1,1,0:162.12
0,1,0:162.12
-1,1,0:162.12
1,0,0:162.12
0,0,0:162.12
