[META]
version=2.0
spawnOnBlockType=2,3
spawnSunlight=True
spawnDarkness=True
spawnWater=False
spawnLava=False
underFill=False
randomRotation=True
dig=True
tree=True
branch=False
needsFoundation=True
rarity=100
collisionPercentage=20
spawnElevationMin=0
spawnElevationMax=200
spawnInBiome=Custom
[DATA]
-1,-1,-3:17.13
-2,1,-3:17.13
-1,-1,-2:17.13
-3,0,-2:17.13
-2,0,-2:17.13
-2,1,-2:17.13
-2,-1,-1:17.13
-1,-1,-1:17.13
-3,0,-1:17.13
-2,0,-1:17.13
-1,0,-1:17.13
-2,1,-1:17.13
-2,-1,0:17.13
-1,-1,0:17.13
-3,0,0:17.13
-2,0,0:17.13
-1,0,0:17.13
-2,1,0:17.13
-1,-1,1:17.13
-2,0,1:17.13
-1,0,1:17.13
-2,0,2:17.13
-1,0,2:17.13
-2,0,3:17.13
-1,0,3:17.13
-2,0,4:17.13
-2,0,5:17.13
-2,0,6:17.13
-2,0,7:17.13
-2,1,8:17.13
-2,1,9:17.13
-2,1,10:17.13
-2,1,11:17.13
-2,1,12:17.13
-2,1,13:17.13
-1,0,14:17.13
-2,1,14:17.13
-1,0,15:17.13
-1,0,16:17.13
-1,0,17:17.13
1,-2,18:161.12
2,-2,18:161.12
1,-1,18:161.12
-1,0,18:17.13
-3,4,18:161.12
-1,4,18:161.12
0,-4,19:161.12
3,-2,19:161.12
-1,-1,19:161.12
0,-1,19:17.13
1,-1,19:161.12
3,-1,19:161.12
-1,0,19:17.13
0,0,19:161.12
-1,1,19:17.13
0,3,19:161.12
-3,5,19:161.12
-2,5,19:161.12
-1,-3,20:161.12
1,-3,20:161.12
1,-2,20:17.13
0,-1,20:161.12
3,-1,20:161.12
-1,0,20:17.13
1,0,20:161.12
-2,1,20:161.12
-2,2,20:17.13
-3,3,20:161.12
-2,3,20:17.13
-3,4,20:161.12
-2,4,20:161.12
1,-4,21:161.12
0,-2,21:161.12
3,-2,21:161.12
-1,-1,21:161.12
1,-1,21:161.12
2,-1,21:161.12
-1,0,21:17.13
1,0,21:161.12
-2,1,21:161.12
-1,1,21:161.12
-2,3,21:161.12
-1,3,21:161.12
-3,-3,22:161.12
-1,-2,22:161.12
0,-2,22:161.12
1,-2,22:161.12
-1,-1,22:17.13
0,-1,22:161.4
1,-1,22:161.12
-3,0,22:161.12
-1,0,22:17.13
0,0,22:161.12
-4,1,22:161.12
-3,2,22:161.12
-1,2,22:161.12
1,2,22:161.4
2,2,22:161.4
-3,4,22:161.12
-1,-3,23:161.12
1,-3,23:161.12
-3,-2,23:161.12
-2,-2,23:161.12
-1,-2,23:17.13
0,-2,23:161.12
1,-2,23:161.12
-3,-1,23:161.12
-2,-1,23:161.12
-1,-1,23:161.12
0,-1,23:161.4
1,-1,23:161.12
-4,0,23:161.12
-3,0,23:161.12
-2,0,23:17.13
-1,0,23:17.13
0,0,23:161.4
2,0,23:161.4
-2,1,23:161.4
0,1,23:17.13
-2,2,23:161.12
0,2,23:161.4
1,2,23:161.4
0,3,23:161.4
1,3,23:161.4
-1,-4,24:161.12
0,-4,24:161.12
-2,-3,24:161.12
1,-3,24:161.12
-4,-2,24:161.12
-3,-2,24:161.12
-2,-2,24:161.12
-1,-2,24:161.12
0,-2,24:17.13
-1,-1,24:161.12
1,-1,24:161.12
-3,0,24:17.13
-2,0,24:161.12
-1,0,24:17.13
1,0,24:17.13
-3,1,24:161.12
-2,1,24:161.12
-1,1,24:161.12
1,1,24:161.4
-4,2,24:161.12
-3,2,24:161.12
-2,2,24:161.12
0,2,24:17.13
0,-3,25:161.12
-1,-2,25:161.12
0,-2,25:161.12
-5,-1,25:161.12
-2,-1,25:161.12
-1,-1,25:161.12
0,-1,25:161.12
-3,0,25:161.12
-2,0,25:161.12
-1,0,25:17.13
0,0,25:161.12
-3,1,25:161.12
-2,1,25:161.12
-1,1,25:161.12
0,2,25:161.4
1,2,25:161.4
-1,-2,26:161.12
0,-2,26:161.12
-2,-1,26:161.12
-1,-1,26:161.12
-4,0,26:161.12
0,0,26:161.12
-1,2,26:161.12
-2,0,27:161.12
-1,0,27:161.12
0,0,27:161.12
0,1,27:161.12
