[META]
version=2.0
spawnOnBlockType=2,3
spawnSunlight=True
spawnDarkness=True
spawnWater=False
spawnLava=False
underFill=False
randomRotation=True
dig=True
tree=True
branch=False
needsFoundation=True
rarity=100
collisionPercentage=20
spawnElevationMin=0
spawnElevationMax=200
spawnInBiome=Custom
[DATA]
-2,2,0:162.0
-2,2,1:162.0
-2,2,2:162.0
-2,2,3:162.0
-2,2,4:162.0
-2,2,5:162.0
-2,2,6:162.0
-2,2,7:162.0
-2,2,8:162.0
-2,2,9:162.0
-2,2,10:162.0
-2,2,11:162.0
-2,2,12:162.0
-2,2,13:162.0
-2,2,14:162.0
-2,-1,15:161.4
-2,2,15:162.0
-3,-2,16:161.4
-2,2,16:162.0
-3,-3,17:161.4
-4,-2,17:161.4
-3,-2,17:161.4
-2,-2,17:161.4
-3,-1,17:162.4
-5,0,17:161.4
-3,0,17:161.4
-2,0,17:162.8
-3,1,17:161.4
-2,1,17:162.8
-2,2,17:162.0
-2,-3,18:161.4
-5,-2,18:161.4
-3,-2,18:161.4
-3,-1,18:161.4
-2,-1,18:161.4
-2,0,18:161.12
-3,1,18:161.4
-2,2,18:162.0
-1,2,18:161.12
-4,3,18:161.12
-3,3,18:161.12
-2,3,18:162.8
-3,4,18:161.12
-2,4,18:161.12
0,4,18:161.12
-1,5,18:161.4
-3,6,18:161.4
-2,6,18:161.4
-3,-2,19:161.4
-3,-1,19:161.4
-3,0,19:161.4
0,0,19:161.12
-2,1,19:161.12
-1,1,19:161.12
-3,2,19:161.12
-2,2,19:162.0
-3,3,19:161.12
-2,4,19:162.8
-1,4,19:161.12
-4,5,19:161.4
-2,5,19:161.4
-1,-1,20:161.12
-3,0,20:161.12
-1,0,20:161.12
-2,1,20:161.12
-1,1,20:162.8
0,1,20:161.12
1,1,20:161.12
-5,2,20:161.12
-2,2,20:162.0
-1,2,20:161.12
0,3,20:161.12
-4,4,20:161.12
-2,4,20:161.12
-1,4,20:161.12
-4,5,20:161.4
-3,5,20:161.4
0,5,20:161.4
-3,0,21:161.12
-2,0,21:161.12
-1,0,21:161.12
-3,2,21:162.4
-2,2,21:162.0
-1,2,21:161.12
-4,3,21:161.12
-2,3,21:161.12
-2,4,21:161.12
-3,-1,22:161.4
-1,-1,22:161.4
-4,0,22:161.4
-3,0,22:161.4
-2,0,22:161.4
0,0,22:161.4
-5,1,22:161.4
-4,1,22:161.4
-2,1,22:161.4
-1,1,22:161.4
0,1,22:161.4
-4,2,22:161.4
-2,2,22:162.0
-1,2,22:161.4
-1,3,22:162.8
-3,4,22:161.4
-1,-1,23:161.4
-3,0,23:161.4
-2,0,23:161.4
-1,0,23:161.4
-4,1,23:161.4
-2,1,23:162.8
-1,1,23:161.4
-3,2,23:161.4
-2,2,23:162.0
-3,3,23:161.4
-2,3,23:161.4
-2,-1,24:161.4
-1,-1,24:161.4
-2,1,24:161.4
-4,2,24:161.4
-2,2,24:162.0
-1,2,24:161.12
-2,3,24:161.4
-2,0,25:161.4
-3,1,25:161.4
0,1,25:161.12
-2,2,25:162.0
0,2,25:161.12
-2,3,25:161.12
-1,3,25:161.12
-3,4,25:161.12
-3,0,26:161.12
-2,0,26:161.12
-2,1,26:161.12
-4,2,26:161.12
-2,2,26:162.0
-1,2,26:161.12
0,2,26:161.12
-4,3,26:161.12
-3,3,26:161.12
-2,4,26:161.12
-1,0,27:161.4
-2,1,27:161.4
-3,2,27:161.4
-1,3,27:161.4
-3,1,28:161.4
-3,2,28:161.4
-2,2,28:161.4
-2,3,28:161.4
