[META]
version=2.0
spawnOnBlockType=2,3
spawnSunlight=True
spawnDarkness=True
spawnWater=False
spawnLava=False
underFill=False
randomRotation=True
dig=True
tree=True
branch=False
needsFoundation=True
rarity=100
collisionPercentage=20
spawnElevationMin=0
spawnElevationMax=200
spawnInBiome=Custom
[DATA]
-1,1,0:162.13
2,-1,1:18.14
2,0,1:18.14
-1,1,1:162.13
-2,-3,2:18.14
-1,-2,2:18.14
0,-2,2:18.14
1,-1,2:18.14
2,-1,2:18.14
-3,0,2:18.14
-2,0,2:18.14
0,0,2:18.14
2,0,2:18.14
-2,1,2:18.14
-1,1,2:162.13
1,1,2:18.14
-3,2,2:18.14
-2,-3,3:18.14
-3,-2,3:18.14
-1,-2,3:18.14
0,-2,3:18.14
1,-2,3:18.14
-4,-1,3:18.14
-2,-1,3:18.14
-1,-1,3:18.14
1,-1,3:18.14
2,-1,3:18.14
-3,0,3:18.14
-2,0,3:18.14
-1,0,3:18.14
0,0,3:18.14
2,0,3:18.14
-2,1,3:18.14
-1,1,3:162.13
0,1,3:18.14
1,1,3:18.14
-3,2,3:18.14
0,2,3:18.14
-3,-3,4:18.14
-2,-3,4:18.14
-3,-2,4:18.14
-1,-2,4:18.14
0,-2,4:18.14
1,-2,4:18.14
-4,-1,4:18.14
-2,-1,4:18.14
-1,-1,4:18.14
0,-1,4:162.13
1,-1,4:18.14
2,-1,4:18.14
-3,0,4:18.14
-2,0,4:18.14
-1,0,4:18.14
0,0,4:162.13
2,0,4:18.14
-3,1,4:18.14
-2,1,4:18.14
-1,1,4:162.13
0,1,4:18.14
1,1,4:18.14
-3,2,4:18.14
-2,2,4:18.14
-1,2,4:18.14
0,2,4:18.14
-2,3,4:18.14
-2,4,4:18.14
-3,-3,5:18.14
-2,-3,5:18.14
-4,-2,5:18.14
-1,-2,5:18.14
-4,-1,5:18.14
-1,-1,5:18.14
1,-1,5:18.14
-3,0,5:18.14
-1,0,5:18.14
0,0,5:18.14
1,0,5:18.14
2,0,5:18.14
-3,1,5:18.14
-2,1,5:18.14
-1,1,5:162.13
0,1,5:18.14
-3,2,5:18.14
-2,2,5:18.14
-1,2,5:18.14
0,2,5:18.14
-2,3,5:18.14
-1,3,5:18.14
0,3,5:18.14
-2,4,5:18.14
-4,-3,6:18.14
-3,-3,6:18.14
-2,-3,6:18.14
-4,-2,6:18.14
-1,-2,6:18.14
-4,-1,6:18.14
-3,-1,6:162.13
-2,-1,6:18.14
-1,-1,6:18.14
-3,0,6:18.14
-2,0,6:162.13
-1,0,6:18.14
0,0,6:18.14
1,0,6:18.14
-3,1,6:18.14
-2,1,6:18.14
-1,1,6:162.13
0,1,6:18.14
-3,2,6:18.14
-2,2,6:18.14
-1,2,6:18.14
0,2,6:18.14
-2,3,6:18.14
-1,3,6:18.14
0,3,6:18.14
-2,4,6:18.14
-3,-3,7:18.14
-2,-3,7:18.14
-4,-1,7:18.14
-3,-1,7:18.14
-2,-1,7:18.14
-3,0,7:18.14
-2,0,7:18.14
-1,0,7:18.14
-2,1,7:18.14
-1,1,7:18.14
-3,2,7:18.14
-2,2,7:18.14
-1,2,7:162.13
0,2,7:18.14
-1,3,7:18.14
-2,4,7:18.14
0,4,7:18.14
-3,-1,8:18.14
-2,-1,8:18.14
-3,0,8:18.14
-2,0,8:18.14
-1,0,8:18.14
-1,1,8:18.14
1,1,8:18.14
-3,2,8:18.14
-2,2,8:18.14
-1,2,8:162.13
-1,3,8:18.14
0,3,8:162.13
-2,4,8:18.14
0,4,8:18.14
-2,0,9:18.14
-1,1,9:18.14
1,1,9:18.14
-2,2,9:18.14
-1,2,9:18.14
-3,3,9:18.14
-2,3,9:162.13
0,3,9:18.14
-2,4,9:18.14
-2,2,10:18.14
-1,2,10:18.14
-2,3,10:18.6
0,3,10:18.14
