[META]
version=2.0
spawnOnBlockType=2,3
spawnSunlight=True
spawnDarkness=True
spawnWater=False
spawnLava=False
underFill=False
randomRotation=True
dig=True
tree=True
branch=False
needsFoundation=True
rarity=100
collisionPercentage=20
spawnElevationMin=0
spawnElevationMax=200
spawnInBiome=Custom
[DATA]
0,0,0:162.0
0,0,1:162.0
0,0,2:162.0
0,0,3:162.0
1,0,3:161.12
2,0,3:161.12
2,1,3:161.12
-1,-2,4:161.12
0,-2,4:161.12
-1,-1,4:161.12
1,-1,4:162.4
2,-1,4:161.12
0,0,4:162.0
1,0,4:161.12
2,0,4:161.12
0,1,4:161.12
1,1,4:161.12
2,1,4:161.12
0,2,4:161.12
1,2,4:161.12
0,-2,5:161.12
1,-2,5:161.12
-2,-1,5:161.12
0,-1,5:161.12
-2,0,5:161.12
-1,0,5:162.4
0,0,5:162.0
2,0,5:161.12
-2,1,5:161.12
-1,1,5:161.12
2,1,5:161.12
-1,2,5:161.12
0,2,5:161.12
1,2,5:161.12
-1,0,6:161.4
0,0,6:162.0
2,0,6:161.12
0,2,6:161.4
0,-2,7:161.12
1,-2,7:161.12
0,-1,7:161.12
1,-1,7:161.12
0,0,7:162.0
1,0,7:161.12
-1,1,7:161.12
0,1,7:162.8
1,1,7:161.12
0,2,7:161.12
-1,-2,8:161.12
1,-2,8:161.4
-1,-1,8:162.4
1,-1,8:161.4
2,-1,8:161.4
-2,0,8:161.12
-1,0,8:161.12
0,0,8:162.0
1,0,8:162.4
2,0,8:161.4
-1,1,8:161.12
1,1,8:161.4
2,1,8:161.4
0,2,8:161.12
0,-2,9:161.12
-1,-1,9:161.12
0,-1,9:161.12
-1,0,9:161.12
0,0,9:162.0
1,0,9:161.12
2,0,9:161.12
0,1,9:161.12
0,-1,10:161.12
-1,0,10:161.12
0,0,10:161.12
1,0,10:161.12
0,1,10:161.12
0,0,11:161.12
0,0,12:161.4
