[META]
version=2.0
spawnOnBlockType=2,3
spawnSunlight=True
spawnDarkness=True
spawnWater=False
spawnLava=False
underFill=False
randomRotation=True
dig=True
tree=True
branch=False
needsFoundation=True
rarity=100
collisionPercentage=20
spawnElevationMin=0
spawnElevationMax=200
spawnInBiome=Custom
[DATA]
2,-1,0:17.14
2,-1,1:17.14
2,-2,2:18.14
2,-1,2:17.14
2,-3,3:18.14
0,-2,3:18.14
2,-2,3:17.14
2,0,3:18.14
3,0,3:18.14
0,-4,4:18.14
-1,-3,4:18.14
3,-3,4:18.14
5,-3,4:18.14
2,-2,4:17.14
2,-5,5:18.14
2,-4,5:18.14
4,-4,5:18.14
0,-3,5:18.14
1,-2,5:18.14
2,-2,5:17.14
4,-2,5:18.14
5,-2,5:18.14
1,-1,5:17.14
3,0,5:18.14
4,-5,6:18.14
2,-4,6:18.14
0,-3,6:18.14
4,-3,6:18.14
2,-2,6:17.14
-4,-1,6:18.14
1,-1,6:17.14
2,-1,6:18.14
3,-1,6:18.14
4,-1,6:18.14
-4,0,6:18.14
-3,0,6:18.14
-2,1,6:18.14
-4,2,6:18.14
2,3,6:18.14
3,3,6:18.14
3,4,6:18.14
1,-5,7:18.14
2,-5,7:18.14
1,-4,7:18.14
2,-3,7:18.14
5,-3,7:18.14
-2,-2,7:18.14
2,-2,7:17.14
-5,-1,7:18.14
1,0,7:17.14
4,1,7:18.14
0,2,7:18.14
3,2,7:18.14
5,4,7:18.14
4,-4,8:18.14
2,-3,8:17.14
-2,-2,8:18.14
1,-2,8:18.14
2,-2,8:17.14
1,-1,8:18.14
3,-1,8:18.14
4,-1,8:18.14
-4,0,8:18.14
-1,0,8:18.14
1,0,8:17.14
4,2,8:18.14
5,2,8:18.14
-2,3,8:18.14
2,3,8:18.14
2,-5,9:18.14
-1,-4,9:18.14
5,-4,9:18.14
-1,-3,9:18.14
1,-3,9:18.14
2,-3,9:17.14
3,-3,9:18.14
2,-2,9:18.14
0,-1,9:18.14
2,-1,9:18.14
3,-1,9:17.14
-5,0,9:18.6
-4,0,9:18.14
0,0,9:17.14
3,1,9:18.14
-1,3,9:18.14
2,-6,10:18.14
0,-4,10:18.14
1,-4,10:18.14
2,-4,10:18.14
-2,-3,10:18.14
1,-3,10:18.14
2,-3,10:17.14
3,-3,10:18.14
0,-2,10:18.14
0,-1,10:18.14
3,-1,10:17.14
0,0,10:17.14
1,0,10:17.14
-2,1,10:18.14
-1,1,10:18.14
1,1,10:17.14
2,1,10:18.14
3,1,10:18.14
2,3,10:18.14
0,4,10:18.14
2,4,10:18.14
1,-6,11:18.14
1,-5,11:18.14
4,-5,11:18.14
-2,-4,11:18.14
-1,-4,11:18.14
2,-4,11:17.14
3,-4,11:18.14
1,-3,11:17.14
2,-3,11:17.14
3,-3,11:18.14
4,-2,11:18.14
6,-2,11:18.14
7,-2,11:18.14
-3,-1,11:18.14
-1,-1,11:18.14
0,-1,11:18.14
3,-1,11:18.14
1,0,11:18.14
-2,1,11:18.14
1,1,11:17.14
4,1,11:18.14
-2,2,11:18.14
1,2,11:18.14
3,2,11:18.14
1,4,11:18.14
0,-6,12:18.14
1,-6,12:18.14
-1,-5,12:18.14
0,-5,12:18.14
2,-5,12:18.14
4,-5,12:18.14
5,-5,12:18.14
-4,-4,12:18.14
1,-4,12:18.14
2,-4,12:17.14
3,-4,12:18.14
4,-4,12:18.14
-1,-3,12:18.14
1,-3,12:17.14
2,-3,12:18.14
3,-3,12:18.14
-4,-2,12:18.14
1,-2,12:18.14
4,-2,12:18.14
5,-2,12:18.14
0,0,12:18.14
3,0,12:18.14
0,1,12:17.14
1,1,12:17.14
1,2,12:17.14
1,-6,13:18.14
2,-6,13:18.14
1,-5,13:18.14
-3,-4,13:18.14
0,-4,13:18.14
2,-4,13:17.14
3,-4,13:17.14
4,-4,13:18.14
-1,-3,13:18.14
1,-3,13:17.14
2,-3,13:18.14
6,-3,13:18.14
3,-2,13:18.14
-2,-1,13:18.14
4,-1,13:18.14
0,0,13:18.14
0,1,13:17.14
1,1,13:18.14
0,2,13:18.14
1,2,13:17.14
2,2,13:18.14
3,2,13:18.14
0,3,13:18.14
4,-6,14:18.14
-2,-5,14:18.14
3,-5,14:18.14
3,-4,14:17.14
4,-4,14:18.14
-2,-3,14:18.14
1,-3,14:17.14
-4,-2,14:18.14
0,-2,14:18.14
-6,-1,14:18.6
4,-1,14:18.14
-4,1,14:18.14
0,1,14:17.14
1,1,14:18.14
4,1,14:18.14
0,2,14:18.14
1,2,14:17.14
2,2,14:17.14
3,2,14:18.14
1,3,14:18.14
2,-6,15:18.14
5,-6,15:18.14
2,-5,15:18.14
4,-5,15:18.14
-1,-4,15:18.14
1,-4,15:17.14
2,-4,15:18.14
3,-4,15:17.14
4,-4,15:17.14
1,-3,15:17.14
-4,-1,15:18.14
2,-1,15:18.14
-2,0,15:18.14
0,0,15:18.14
3,0,15:18.14
7,0,15:18.14
-3,1,15:18.14
0,1,15:17.14
1,1,15:18.14
2,2,15:17.14
1,3,15:18.14
2,3,15:18.14
-1,4,15:18.14
0,4,15:18.14
3,5,15:18.14
2,-6,16:18.14
4,-5,16:18.14
0,-4,16:18.14
1,-4,16:17.14
2,-4,16:18.14
4,-4,16:17.14
6,-4,16:18.14
-5,-3,16:18.6
1,-3,16:18.14
-5,-2,16:18.14
0,-2,16:18.14
7,-1,16:18.14
-5,0,16:18.14
0,0,16:18.14
1,0,16:18.14
4,1,16:18.14
2,2,16:17.14
4,2,16:18.14
-1,3,16:18.14
2,3,16:18.14
3,3,16:18.14
4,3,16:18.14
5,3,16:18.14
0,4,16:18.14
4,4,16:18.14
1,5,16:18.14
5,-7,17:18.14
3,-6,17:18.14
0,-5,17:18.14
1,-5,17:18.14
4,-5,17:17.14
1,-4,17:17.14
4,-4,17:17.14
2,-2,17:18.14
-2,0,17:18.14
0,0,17:18.14
4,0,17:18.14
7,0,17:18.14
-2,1,17:18.14
-1,1,17:18.14
0,1,17:18.14
5,1,17:18.14
-1,2,17:18.14
2,2,17:18.14
0,-7,18:18.14
4,-7,18:18.14
6,-7,18:18.14
-1,-6,18:18.14
4,-6,18:18.14
1,-5,18:18.14
2,-5,18:18.14
5,-5,18:18.14
-1,-4,18:18.14
0,-4,18:18.14
1,-4,18:17.14
4,-4,18:18.14
7,-4,18:18.14
-1,-3,18:18.14
-1,-2,18:18.14
2,-2,18:18.14
3,-2,18:18.14
-1,1,18:18.14
0,1,18:18.14
1,1,18:18.14
-1,2,18:18.14
1,-6,19:18.14
-2,-5,19:18.14
1,-5,19:18.14
4,-5,19:18.14
5,-4,19:18.14
6,-4,19:18.14
-2,-3,19:18.14
0,-3,19:18.14
3,-3,19:18.14
5,-2,19:18.14
4,-1,19:18.14
5,-5,20:18.14
-1,-4,20:18.14
-1,-3,20:18.14
0,-3,20:18.14
4,-5,18:18.14
