[META]
version=2.0
spawnOnBlockType=2,3
spawnSunlight=True
spawnDarkness=True
spawnWater=False
spawnLava=False
underFill=False
randomRotation=True
dig=True
tree=True
branch=False
needsFoundation=True
rarity=100
collisionPercentage=20
spawnElevationMin=0
spawnElevationMax=200
spawnInBiome=Custom
[DATA]
1,0,-3:162.13
1,0,-2:162.13
0,1,-2:162.13
1,-1,-1:162.13
1,0,-1:162.13
2,0,-1:162.13
0,1,-1:162.13
1,-1,0:162.13
1,0,0:162.13
2,0,0:162.13
0,1,0:162.13
1,0,1:162.13
0,-2,2:161.13
-1,-1,2:161.13
0,-1,2:161.13
1,-1,2:161.13
-1,0,2:161.13
1,0,2:162.13
-1,-4,3:161.13
1,-3,3:161.13
1,-2,3:161.13
2,-2,3:161.13
-2,-1,3:161.13
-1,-1,3:161.13
2,-1,3:161.13
1,0,3:162.13
-1,1,3:161.13
-2,2,3:161.13
-1,-5,4:161.13
-3,-4,4:161.13
-1,-4,4:161.13
-3,-3,4:161.13
-1,-3,4:161.13
0,-3,4:161.13
1,-2,4:161.13
-3,-1,4:161.13
0,-1,4:162.13
2,-1,4:161.13
-4,0,4:161.13
-2,0,4:161.13
1,0,4:162.13
2,0,4:161.13
-2,1,4:161.13
-1,1,4:161.13
1,1,4:161.13
2,1,4:161.13
4,1,4:161.13
-2,2,4:161.13
2,3,4:161.13
1,4,4:161.13
-1,-5,5:161.13
-4,-4,5:161.13
-2,-4,5:161.13
1,-4,5:161.13
2,-4,5:161.13
-5,-3,5:161.13
-2,-3,5:161.13
-1,-3,5:161.13
0,-2,5:161.13
1,-2,5:162.13
2,-2,5:161.13
-3,-1,5:161.13
-1,-1,5:162.13
-5,0,5:161.5
1,0,5:161.13
-5,1,5:161.5
-2,1,5:161.13
0,1,5:161.13
1,1,5:162.13
2,1,5:161.13
-1,2,5:161.13
1,2,5:161.13
2,2,5:161.13
-2,3,5:161.13
0,3,5:161.13
1,3,5:161.13
2,3,5:161.13
1,4,5:161.13
-1,-5,6:161.13
1,-5,6:161.13
-3,-4,6:161.13
-2,-4,6:161.13
0,-4,6:161.13
2,-4,6:161.13
-3,-3,6:161.13
1,-3,6:161.13
-4,-2,6:161.13
2,-2,6:161.13
3,-2,6:161.13
-3,-1,6:161.13
-2,-1,6:161.13
-1,-1,6:162.13
2,-1,6:161.13
-3,0,6:161.13
-2,0,6:161.13
0,0,6:161.13
3,0,6:161.13
-4,1,6:161.13
-3,1,6:161.13
-2,1,6:161.13
-1,1,6:161.13
1,1,6:162.13
2,1,6:161.13
4,1,6:161.13
5,1,6:161.13
-4,2,6:161.13
-3,2,6:161.13
1,2,6:161.13
2,2,6:161.13
3,2,6:161.13
-3,3,6:161.13
-2,-5,7:161.13
-1,-5,7:161.13
-3,-4,7:161.13
-1,-4,7:161.13
2,-3,7:161.13
3,-3,7:161.13
-3,-1,7:161.13
-2,-1,7:161.13
-1,-1,7:161.13
0,-1,7:161.13
2,-1,7:161.13
-2,0,7:161.13
2,0,7:161.13
3,0,7:161.13
-4,1,7:161.13
-3,1,7:161.13
-2,1,7:161.13
-1,1,7:161.13
0,1,7:161.13
1,1,7:162.13
2,1,7:161.13
-3,2,7:161.13
2,2,7:162.13
-2,3,7:161.13
-1,3,7:161.13
3,3,7:161.13
1,4,7:161.13
3,4,7:161.13
0,-4,8:161.13
-2,-3,8:161.13
1,-3,8:161.13
1,-2,8:161.13
0,-1,8:161.13
1,-1,8:161.13
3,-1,8:161.13
0,0,8:161.13
-2,1,8:161.13
0,1,8:161.13
4,1,8:161.13
0,2,8:161.13
1,2,8:161.13
2,3,8:161.13
-1,-3,9:161.5
-2,-1,9:161.5
0,-1,9:161.5
1,-1,9:161.5
4,-1,9:161.5
-2,1,9:161.5
0,1,9:161.5
1,1,9:161.13
2,1,9:161.13
-2,2,9:161.5
-1,2,9:161.5
0,2,9:161.5
-2,3,9:161.5
1,-2,10:161.5
-1,-1,10:161.5
0,-1,10:161.5
-1,1,10:161.5
