[META]
version=2.0
spawnOnBlockType=2,3
spawnSunlight=True
spawnDarkness=True
spawnWater=False
spawnLava=False
underFill=False
randomRotation=True
dig=True
tree=True
branch=False
needsFoundation=True
rarity=100
collisionPercentage=20
spawnElevationMin=0
spawnElevationMax=200
spawnInBiome=Custom
[DATA]
0,-1,-3:162.13
2,0,-3:162.13
-1,1,-3:162.13
0,-2,-2:162.13
0,-1,-2:162.13
-2,0,-2:162.13
1,0,-2:162.13
2,0,-2:162.13
-1,1,-2:162.13
2,1,-2:162.13
0,2,-2:162.13
0,-2,-1:162.13
0,-1,-1:162.13
-2,0,-1:162.13
-1,0,-1:162.13
0,0,-1:162.13
1,0,-1:162.13
2,0,-1:162.13
-1,1,-1:162.13
0,1,-1:162.13
2,1,-1:162.13
0,2,-1:162.13
0,-2,0:162.13
0,-1,0:162.13
-2,0,0:162.13
-1,0,0:162.13
0,0,0:162.13
1,0,0:162.13
2,0,0:162.13
-1,1,0:162.13
0,1,0:162.13
2,1,0:162.13
0,2,0:162.13
0,-1,1:162.13
-1,0,1:162.13
0,0,1:162.13
1,0,1:162.13
0,1,1:162.13
3,-4,2:161.13
-1,0,2:162.13
0,0,2:162.13
0,1,2:162.13
-7,5,2:161.13
-5,5,2:161.13
-8,6,2:161.13
-6,7,2:161.13
-2,7,2:161.13
3,-8,3:161.5
5,-7,3:161.5
2,-6,3:161.13
2,-5,3:161.13
3,-2,3:161.13
4,-2,3:161.13
0,0,3:162.13
-4,1,3:161.13
-3,1,3:161.13
0,1,3:162.13
-6,2,3:161.13
-3,2,3:161.13
4,2,3:161.13
-5,3,3:161.13
-5,4,3:161.13
-4,4,3:161.13
-3,4,3:161.13
6,4,3:161.13
-6,5,3:161.5
-5,5,3:161.13
-3,5,3:161.13
-3,6,3:161.13
-1,6,3:161.13
-2,7,3:161.5
3,-9,4:161.5
5,-8,4:161.5
3,-7,4:161.5
-1,-5,4:161.13
4,-5,4:161.13
4,-4,4:161.13
5,-4,4:161.13
1,-3,4:162.13
3,-3,4:161.13
1,-2,4:162.13
0,-1,4:162.13
0,0,4:162.13
0,1,4:162.13
-3,2,4:161.13
-4,3,4:161.13
7,3,4:161.5
-7,4,4:161.5
-4,4,4:161.13
-3,4,4:161.13
-2,4,4:161.13
1,4,4:161.13
4,4,4:161.13
6,4,4:161.13
-5,5,4:161.13
-3,5,4:161.13
6,5,4:161.13
7,5,4:161.5
-9,6,4:161.5
-7,6,4:161.5
-6,6,4:161.5
-5,6,4:162.13
-3,6,4:161.13
-1,6,4:161.13
6,6,4:161.5
-9,7,4:161.5
-7,7,4:161.5
4,7,4:161.5
-5,9,4:161.13
2,-7,5:161.5
0,-4,5:161.13
2,-4,5:162.13
3,-3,5:161.13
3,-2,5:161.13
-3,0,5:161.13
0,0,5:162.13
1,0,5:161.13
0,1,5:162.13
-4,2,5:161.13
-3,2,5:161.13
-1,2,5:162.13
0,2,5:161.13
3,2,5:161.13
-6,3,5:161.5
2,3,5:161.13
5,3,5:161.13
2,4,5:161.13
-4,5,5:162.13
-1,5,5:161.13
-7,6,5:161.5
-6,6,5:161.5
-9,7,5:161.5
5,7,5:161.5
6,7,5:161.5
-4,8,5:161.5
4,8,5:161.5
-4,9,5:161.5
5,-8,6:161.5
6,-8,6:161.5
2,-6,6:161.5
5,-6,6:161.5
1,-5,6:161.13
3,-5,6:162.13
7,-4,6:161.5
0,-2,6:161.13
1,-2,6:161.13
3,-2,6:161.13
4,-2,6:161.13
1,-1,6:161.13
5,-1,6:161.5
-5,0,6:161.13
0,0,6:162.13
1,0,6:161.13
-6,1,6:161.5
-1,1,6:161.13
0,1,6:162.13
-3,2,6:161.13
4,2,6:161.13
-3,3,6:161.13
-2,3,6:162.13
4,3,6:161.13
-7,4,6:161.5
-5,4,6:161.13
-3,4,6:162.13
-2,4,6:161.13
-1,4,6:161.13
1,4,6:161.13
3,4,6:161.13
5,4,6:161.5
0,5,6:161.13
2,5,6:161.13
7,5,6:161.5
-3,6,6:161.5
5,6,6:161.5
-5,7,6:161.5
-4,7,6:161.5
-7,8,6:161.5
-5,8,6:161.5
-4,8,6:161.5
-1,8,6:161.5
4,8,6:161.5
-5,9,6:161.5
3,-9,7:161.5
0,-7,7:161.5
1,-6,7:161.5
7,-6,7:161.5
2,-5,7:161.13
4,-5,7:161.13
2,-3,7:161.13
3,-3,7:161.13
-2,0,7:161.13
0,0,7:162.13
4,0,7:161.13
6,0,7:161.5
-1,1,7:161.13
1,1,7:161.13
2,1,7:161.13
3,1,7:161.13
5,1,7:161.5
0,2,7:161.13
1,2,7:162.13
5,2,7:161.5
-7,3,7:161.5
-3,3,7:161.13
0,3,7:161.13
2,3,7:161.13
4,3,7:161.13
-6,4,7:161.5
-5,4,7:161.5
-3,4,7:161.13
0,4,7:161.13
1,4,7:161.13
3,4,7:161.13
4,4,7:162.13
6,4,7:161.5
8,4,7:161.5
-1,5,7:161.13
0,5,7:161.13
4,5,7:161.13
-7,6,7:161.5
-6,6,7:161.5
-3,6,7:161.5
-1,6,7:161.5
0,6,7:161.5
1,6,7:161.5
3,6,7:161.5
4,7,7:161.5
-6,9,7:161.5
3,-9,8:161.5
3,-8,8:161.5
2,-5,8:161.13
5,-5,8:161.5
-2,-4,8:161.13
2,-3,8:161.13
4,-2,8:161.13
3,-1,8:161.13
-1,0,8:161.13
0,0,8:162.13
1,0,8:162.13
3,0,8:161.13
4,0,8:161.13
-3,1,8:161.13
-1,1,8:162.13
-2,2,8:161.13
2,2,8:161.13
4,2,8:161.13
0,3,8:161.13
1,3,8:161.13
2,3,8:162.13
3,3,8:162.13
6,3,8:161.5
-7,4,8:161.5
-6,4,8:161.5
-4,4,8:161.13
7,4,8:161.5
3,6,8:161.5
4,6,8:161.5
5,6,8:161.5
0,7,8:161.5
5,8,8:161.5
5,-7,9:161.5
1,-5,9:161.5
3,-5,9:161.5
4,-5,9:161.5
3,-3,9:161.5
-5,-2,9:161.5
-4,-2,9:161.5
-3,-2,9:161.5
-1,-1,9:162.13
0,0,9:162.13
1,0,9:162.13
-3,1,9:161.5
-5,2,9:161.5
-2,2,9:161.5
-1,2,9:162.13
0,2,9:161.5
-5,3,9:161.5
-3,3,9:161.5
-2,3,9:161.5
1,3,9:161.5
4,3,9:161.5
-3,4,9:161.5
-2,4,9:161.5
-1,4,9:161.5
1,4,9:161.5
3,4,9:161.5
1,5,9:161.5
2,5,9:161.5
-2,6,9:161.5
3,6,9:161.5
4,6,9:161.5
-3,7,9:161.5
4,8,9:161.5
0,-5,10:161.5
4,-5,10:161.5
-5,-4,10:161.5
-3,-4,10:161.5
3,-3,10:161.5
-6,-2,10:161.5
-3,-2,10:161.5
-4,-1,10:161.5
-1,-1,10:162.13
2,-1,10:161.5
0,0,10:162.13
2,0,10:162.13
-4,1,10:161.5
-3,1,10:161.5
3,1,10:161.5
-1,2,10:162.13
2,2,10:161.5
5,2,10:161.5
-4,3,10:161.5
-1,3,10:161.5
0,3,10:161.5
3,3,10:161.5
6,3,10:161.5
7,3,10:161.5
-4,4,10:161.5
-3,4,10:161.5
1,4,10:161.5
4,4,10:161.5
6,4,10:161.5
-2,5,10:161.5
2,5,10:161.5
2,6,10:161.5
3,6,10:161.5
-3,-6,11:161.5
0,-3,11:161.5
5,-3,11:161.5
-6,-2,11:161.5
-2,-2,11:162.13
1,-2,11:161.5
-5,-1,11:161.5
-2,-1,11:161.5
3,-1,11:161.5
5,-1,11:161.5
6,-1,11:161.5
0,0,11:162.13
2,0,11:162.13
2,1,11:161.5
-2,2,11:162.13
-3,3,11:161.5
5,3,11:161.5
-4,4,11:161.5
0,4,11:161.5
5,4,11:161.5
-4,5,11:161.5
-2,5,11:161.5
2,6,11:161.5
-2,-5,12:161.5
1,-5,12:161.5
-5,-4,12:161.5
-4,-4,12:161.5
2,-4,12:161.5
-6,-3,12:161.5
-5,-3,12:161.5
-2,-3,12:161.5
-2,-2,12:162.13
0,-2,12:161.5
-5,-1,12:161.5
-1,-1,12:161.5
0,-1,12:162.13
4,-1,12:161.5
-3,0,12:161.5
-2,0,12:161.5
-1,0,12:161.5
0,0,12:162.13
1,0,12:161.5
3,0,12:162.13
7,0,12:161.5
-5,1,12:161.5
-4,1,12:161.5
-3,1,12:161.5
0,1,12:161.5
3,1,12:161.5
-2,2,12:162.13
-1,2,12:161.5
3,2,12:161.5
4,2,12:161.5
5,2,12:161.5
-5,3,12:161.5
-3,3,12:161.5
0,3,12:161.5
1,3,12:161.5
2,3,12:161.5
3,3,12:161.5
4,3,12:161.5
-1,5,12:161.5
-3,7,12:161.5
4,-4,13:161.13
6,-4,13:161.5
-4,-3,13:161.13
-3,-3,13:162.13
4,-3,13:161.13
6,-3,13:161.5
-6,-2,13:161.5
-4,-2,13:161.13
-2,-2,13:161.13
0,-2,13:162.13
3,-2,13:161.13
4,-2,13:161.13
6,-1,13:161.5
0,0,13:162.13
3,0,13:162.13
7,0,13:161.5
8,0,13:161.5
-5,1,13:161.5
-2,1,13:161.13
1,1,13:161.13
4,1,13:161.13
3,2,13:161.13
5,2,13:161.5
7,2,13:161.5
-4,3,13:161.13
-2,3,13:162.13
-5,4,13:161.5
-4,4,13:161.13
0,4,13:161.13
-2,5,13:161.5
1,5,13:161.5
-5,6,13:161.5
-2,7,13:161.5
0,7,13:161.5
-2,-5,14:161.5
-2,-4,14:161.13
5,-4,14:161.5
-3,-3,14:162.13
0,-3,14:162.13
5,-3,14:161.5
-4,-2,14:161.13
-2,-2,14:161.13
1,-2,14:161.13
2,-2,14:161.13
3,-2,14:161.13
-4,-1,14:161.13
-3,-1,14:161.13
-2,-1,14:161.13
8,-1,14:161.5
9,-1,14:161.5
0,0,14:162.13
4,0,14:162.13
8,0,14:161.5
-2,1,14:161.13
-2,2,14:161.13
-1,2,14:161.13
4,3,14:161.13
-3,4,14:162.13
2,4,14:161.13
3,-5,15:161.13
5,-5,15:161.13
6,-5,15:161.5
2,-4,15:161.13
5,-4,15:161.13
8,-4,15:161.5
-5,-3,15:161.5
-4,-3,15:161.13
-2,-3,15:161.13
0,-3,15:162.13
1,-3,15:161.13
3,-3,15:161.13
5,-3,15:161.13
-3,-2,15:161.13
3,-2,15:161.13
9,-2,15:161.5
-3,-1,15:161.13
1,-1,15:162.13
4,-1,15:161.13
5,-1,15:162.13
-4,0,15:161.13
-1,0,15:161.13
0,0,15:162.13
3,0,15:161.13
5,0,15:162.13
9,0,15:161.5
-3,1,15:161.13
6,1,15:162.13
-4,2,15:161.13
-2,2,15:161.13
2,2,15:161.13
5,2,15:161.13
7,2,15:161.5
8,2,15:161.5
-1,3,15:161.13
2,3,15:161.13
6,3,15:161.5
7,3,15:161.5
-5,4,15:161.5
-3,4,15:161.13
-2,4,15:161.13
-4,5,15:161.13
-2,-4,16:161.13
0,-4,16:162.13
5,-4,16:161.13
-1,-3,16:161.13
-2,-2,16:161.13
-1,-2,16:161.13
1,-1,16:162.13
6,-1,16:161.5
-1,0,16:161.13
0,0,16:162.13
4,0,16:161.13
0,2,16:161.13
1,2,16:161.13
3,2,16:161.13
-5,3,16:161.5
-2,3,16:161.13
-1,3,16:161.13
0,3,16:161.13
2,3,16:161.5
4,3,16:161.13
5,3,16:161.13
-1,4,16:161.13
2,4,16:161.5
-2,6,16:161.5
-1,-5,17:161.13
-2,-4,17:161.13
1,-4,17:161.13
4,-4,17:161.13
6,-4,17:161.5
-2,-3,17:161.13
-1,-2,17:161.13
1,-2,17:162.13
3,-2,17:161.13
-3,-1,17:161.13
1,-1,17:161.13
3,-1,17:161.13
5,-1,17:161.13
8,-1,17:161.5
-3,0,17:161.13
0,0,17:162.13
4,0,17:161.13
6,0,17:161.5
7,0,17:161.5
0,1,17:161.13
4,1,17:161.13
8,1,17:161.5
-3,2,17:161.13
-2,2,17:161.13
-1,2,17:161.13
0,2,17:161.13
5,2,17:161.13
-1,4,17:161.13
3,4,17:161.5
-2,5,17:161.13
-1,5,17:161.13
0,5,17:161.13
-1,-6,18:161.13
2,-4,18:161.13
2,-3,18:161.13
1,-2,18:162.13
2,-2,18:161.13
3,-2,18:161.13
-3,-1,18:161.13
-2,-1,18:161.13
0,-1,18:161.13
1,0,18:161.13
5,0,18:161.13
6,0,18:161.5
0,1,18:162.13
3,1,18:161.13
-4,2,18:161.13
-2,2,18:161.13
-1,2,18:161.13
0,2,18:161.13
2,2,18:161.13
3,2,18:161.13
-1,4,18:161.5
2,4,18:161.5
3,4,18:161.5
-2,5,18:161.13
1,5,18:161.5
-1,6,18:161.5
-1,-5,19:161.13
1,-5,19:161.13
2,-5,19:161.13
-4,-4,19:161.13
-1,-4,19:161.13
2,-4,19:161.13
3,-3,19:161.13
-4,-2,19:161.13
-3,-2,19:161.13
-2,-2,19:161.13
-1,-2,19:161.13
1,-2,19:162.13
3,-2,19:161.13
-4,-1,19:161.13
-3,-1,19:161.13
-1,-1,19:161.13
0,-1,19:161.13
1,-1,19:161.13
0,0,19:161.13
2,0,19:161.13
0,1,19:162.13
1,1,19:162.13
5,1,19:161.13
-4,2,19:161.13
-3,2,19:161.13
1,2,19:161.13
5,5,19:161.5
-3,-6,20:161.13
-1,-5,20:161.13
1,-4,20:161.13
2,-3,20:161.5
3,-3,20:161.13
4,-3,20:161.13
-3,-2,20:161.13
-2,-2,20:161.13
1,-2,20:161.13
-5,-1,20:161.5
-4,-1,20:161.13
-1,-1,20:161.13
0,-1,20:161.13
3,-1,20:161.13
4,-1,20:161.13
5,-1,20:161.13
-5,0,20:161.5
-3,0,20:161.13
-1,0,20:161.13
0,0,20:161.13
1,0,20:161.13
2,0,20:161.13
5,0,20:161.13
6,0,20:161.5
-4,1,20:161.13
-3,1,20:161.13
-1,1,20:161.13
3,1,20:161.13
-4,2,20:161.13
1,2,20:161.13
3,2,20:161.13
5,2,20:161.13
-2,3,20:161.13
0,3,20:161.13
1,3,20:161.13
2,3,20:161.5
4,3,20:161.5
5,3,20:161.5
-5,4,20:161.5
-2,4,20:161.5
-1,4,20:161.13
0,4,20:161.13
1,4,20:161.5
2,4,20:161.5
4,4,20:161.5
-1,5,20:161.13
0,5,20:161.5
-1,6,20:161.5
0,-5,21:161.13
-3,-4,21:161.13
-2,-4,21:161.13
-1,-4,21:161.13
0,-3,21:161.13
-3,-2,21:161.13
0,-2,21:161.13
3,-2,21:161.13
4,-2,21:161.13
-2,-1,21:161.13
-1,-1,21:161.13
0,-1,21:161.13
1,-1,21:161.13
-3,0,21:161.13
3,0,21:161.13
-3,1,21:161.13
-1,1,21:161.13
0,1,21:161.13
1,1,21:161.13
-5,2,21:161.5
-4,2,21:161.13
-2,2,21:161.13
0,2,21:161.13
-1,3,21:161.13
2,3,21:161.5
-3,4,21:161.13
1,4,21:161.5
-2,5,21:161.13
-1,6,21:161.5
0,6,21:161.5
-1,-5,22:161.13
-4,-4,22:161.5
-1,-4,22:161.13
-1,-2,22:161.13
2,-2,22:161.13
-1,0,22:161.13
4,0,22:161.13
5,0,22:161.13
-2,1,22:161.13
-1,1,22:161.13
1,2,22:161.13
2,2,22:161.13
3,2,22:161.13
5,2,22:161.13
0,3,22:161.13
-1,4,22:161.13
0,4,22:161.13
1,5,22:161.5
2,6,22:161.5
0,-5,23:161.13
-2,-3,23:161.13
-1,-3,23:161.13
1,-3,23:161.13
5,-3,23:161.13
-2,-2,23:161.13
-2,-1,23:161.13
-1,-1,23:161.13
1,-1,23:161.13
2,-1,23:161.13
-2,0,23:161.13
-1,0,23:161.13
5,0,23:161.13
2,1,23:161.13
5,1,23:161.13
1,2,23:161.13
3,2,23:161.13
3,3,23:161.5
1,-4,24:161.13
-1,-3,24:161.13
0,-3,24:161.13
-2,-2,24:161.13
-1,-2,24:161.13
-1,-1,24:161.13
-1,0,24:161.13
3,1,24:161.13
1,2,24:161.13
2,2,24:161.13
-1,3,24:161.5
-1,4,24:161.5
2,4,24:161.5
2,-4,25:161.13
3,-3,25:161.13
-1,-2,25:161.13
3,-2,25:161.13
4,-1,25:161.13
2,-2,26:161.13
3,-2,26:161.13
4,-2,26:161.13
2,-1,26:161.13
2,-3,23:161.13
-1,2,22:162.13
2,-3,22:161.13
2,2,21:162.13
-1,2,21:162.13
2,-2,21:162.13
2,-3,21:162.13
-1,-3,21:162.13
2,2,20:162.13
0,2,20:162.13
-1,2,20:162.13
2,1,20:162.13
0,1,20:162.13
2,-2,20:162.13
0,-2,20:162.13
-1,-2,20:162.13
-1,-3,20:162.13
2,1,19:162.13
2,-2,19:162.13
0,-2,19:162.13
