[META]
version=2.0
spawnOnBlockType=2,3
spawnSunlight=True
spawnDarkness=True
spawnWater=False
spawnLava=False
underFill=False
randomRotation=True
dig=True
tree=True
branch=False
needsFoundation=True
rarity=100
collisionPercentage=20
spawnElevationMin=0
spawnElevationMax=200
spawnInBiome=Custom
[DATA]
0,-1,-3:17.12
0,-1,-2:17.12
-1,0,-2:17.12
0,-1,-1:17.12
-1,0,-1:17.12
0,-2,1:18.12
-2,-1,1:18.12
0,-1,1:18.12
-1,0,1:18.12
-2,1,1:18.12
0,2,1:18.12
-1,-3,2:18.12
-2,-2,2:18.12
1,-2,2:18.12
-2,-1,2:18.12
0,-1,2:18.12
-2,0,2:18.12
0,0,2:18.12
1,0,2:18.12
-3,1,2:18.12
0,1,2:18.12
2,1,2:18.12
0,2,2:18.12
-1,3,2:18.12
-1,-3,3:18.12
0,-3,3:18.12
-3,-2,3:18.12
-2,-2,3:18.12
-1,-2,3:18.12
0,-2,3:18.12
1,-2,3:18.12
-1,-1,3:18.12
1,-1,3:18.12
2,-1,3:18.12
0,0,3:18.12
1,0,3:18.12
2,0,3:18.12
-2,1,3:18.12
-1,1,3:18.12
0,1,3:18.12
2,1,3:18.12
1,2,3:18.12
1,3,3:18.12
0,-3,4:18.12
0,-2,4:18.12
2,-2,4:18.12
-2,-1,4:18.4
0,-1,4:18.12
1,-1,4:18.12
-3,0,4:18.4
-2,0,4:18.12
-1,2,4:18.12
0,2,4:18.12
0,3,4:18.12
-3,-2,5:18.12
-1,-2,5:18.12
1,-2,5:18.12
-3,-1,5:18.12
-2,0,5:18.12
-1,0,5:18.4
0,0,5:18.12
2,0,5:18.12
-2,1,5:18.12
1,1,5:18.12
-3,2,5:18.12
0,2,5:18.12
2,2,5:18.4
-2,3,5:18.12
-2,-1,6:18.12
-1,-1,6:18.12
-1,0,6:18.12
0,0,6:18.12
1,0,6:18.12
-2,1,6:18.12
-2,2,6:18.12
-1,3,6:18.12
0,-1,7:18.4
-2,0,7:18.4
-1,1,7:18.12
-1,1,6:18.12
-2,0,6:18.12
0,-1,6:18.12
-2,2,5:18.12
-1,1,5:18.12
1,0,5:18.12
-2,-1,5:18.12
-3,2,4:18.12
-2,1,4:18.12
2,0,4:18.12
1,0,4:18.12
0,0,4:18.12
-3,-1,4:18.12
0,3,3:18.12
-1,2,3:18.12
-3,2,3:18.12
-2,0,3:18.12
-3,0,3:18.12
-2,-1,3:18.12
0,3,2:18.12
1,2,2:18.12
-1,1,2:18.12
-1,0,2:18.12
-1,-2,2:18.12
0,-3,2:18.12
0,0,1:18.12
-2,0,1:18.12
-1,-1,1:18.12
0,0,0:18.12
-1,0,0:18.12
0,-1,0:18.12
-1,-1,0:18.12