[META]
version=2.0
spawnOnBlockType=2,3
spawnSunlight=True
spawnDarkness=True
spawnWater=False
spawnLava=False
underFill=False
randomRotation=True
dig=True
tree=True
branch=False
needsFoundation=True
rarity=100
collisionPercentage=20
spawnElevationMin=0
spawnElevationMax=200
spawnInBiome=Custom
[DATA]
0,-1,0:162.13
0,-1,1:162.13
3,-3,2:161.5
2,-2,2:161.5
4,-2,2:161.5
-2,-1,2:161.5
0,-1,2:162.13
4,-1,2:161.5
4,-5,3:161.13
1,-4,3:161.5
3,-4,3:161.13
4,-4,3:161.13
-2,-3,3:161.5
3,-3,3:161.5
-3,-2,3:161.5
4,-2,3:161.5
0,-1,3:162.13
1,-1,3:162.13
2,-1,3:162.13
3,-1,3:161.5
5,-1,3:161.5
6,-1,3:161.5
-1,0,3:161.5
2,0,3:161.5
2,1,3:161.5
3,2,3:161.5
3,-5,4:161.5
4,-5,4:161.5
-2,-4,4:161.5
1,-4,4:161.5
2,-4,4:161.5
3,-4,4:161.5
4,-4,4:161.5
5,-4,4:161.5
-3,-3,4:161.5
1,-3,4:161.5
3,-3,4:161.5
4,-3,4:161.5
-1,-2,4:162.13
1,-2,4:161.5
3,-2,4:162.13
7,-2,4:161.5
-3,-1,4:161.5
-2,-1,4:161.5
-1,-1,4:161.5
0,-1,4:162.13
1,-1,4:161.5
3,-1,4:161.5
4,-1,4:161.5
5,-1,4:161.5
6,-1,4:161.5
7,-1,4:161.5
-1,0,4:161.5
1,0,4:162.13
2,0,4:161.5
4,0,4:161.5
5,0,4:161.5
7,0,4:161.5
0,1,4:161.5
1,1,4:161.5
2,1,4:161.5
5,1,4:161.5
2,2,4:161.5
3,2,4:161.5
2,3,4:161.5
1,-5,5:161.5
3,-5,5:161.5
-3,-3,5:161.5
-2,-3,5:161.5
3,-3,5:161.5
5,-3,5:161.5
6,-3,5:161.5
-4,-2,5:161.5
-3,-2,5:161.5
-2,-2,5:162.13
-1,-2,5:161.5
1,-2,5:161.5
3,-2,5:161.5
5,-2,5:161.5
6,-2,5:161.5
-2,-1,5:161.5
-1,-1,5:161.5
0,-1,5:162.13
3,-1,5:161.5
5,-1,5:161.5
6,-1,5:161.5
7,-1,5:161.13
2,0,5:161.5
3,0,5:161.5
4,0,5:161.5
7,0,5:161.13
1,1,5:161.5
2,1,5:162.13
4,1,5:161.5
5,1,5:161.5
4,2,5:161.5
2,3,5:161.5
-3,-5,6:161.5
-5,-4,6:161.5
1,-4,6:161.5
2,-4,6:161.5
-3,-3,6:161.5
-1,-3,6:161.5
0,-3,6:161.5
1,-3,6:161.5
2,-3,6:161.5
3,-3,6:161.5
-2,-2,6:162.13
0,-2,6:161.5
1,-2,6:162.13
3,-2,6:161.5
6,-2,6:161.5
-2,-1,6:161.5
-1,-1,6:161.5
0,-1,6:162.13
1,-1,6:161.5
3,-1,6:161.5
4,-1,6:161.5
6,-1,6:161.5
-4,0,6:161.5
-1,0,6:161.5
0,0,6:161.5
3,0,6:161.5
-1,1,6:161.5
1,1,6:161.5
2,1,6:161.5
4,2,6:161.5
1,3,6:161.5
1,-5,7:161.5
-5,-4,7:161.5
-4,-4,7:161.5
-3,-4,7:161.5
1,-4,7:161.5
-5,-3,7:161.5
-4,-3,7:161.5
-3,-3,7:162.13
-2,-3,7:161.5
-1,-3,7:161.5
0,-3,7:161.5
1,-3,7:162.13
2,-3,7:161.5
3,-3,7:161.5
5,-3,7:161.5
-5,-2,7:161.5
-3,-2,7:161.5
-1,-2,7:161.5
1,-2,7:161.5
3,-2,7:161.5
4,-2,7:161.5
5,-2,7:161.5
6,-2,7:161.5
-4,-1,7:161.5
-3,-1,7:161.5
-2,-1,7:162.13
-1,-1,7:161.5
0,-1,7:162.13
2,-1,7:161.5
5,-1,7:161.5
6,-1,7:161.5
7,-1,7:161.13
-3,0,7:161.5
5,0,7:161.5
6,0,7:161.13
7,0,7:161.13
-3,1,7:161.5
-2,1,7:161.5
-1,1,7:161.5
1,1,7:161.5
2,1,7:161.5
2,2,7:161.5
-3,-4,8:161.5
-1,-4,8:161.5
0,-4,8:161.5
1,-4,8:161.5
2,-4,8:161.5
3,-4,8:161.5
5,-4,8:161.13
-3,-3,8:161.5
-1,-3,8:161.5
0,-3,8:161.5
1,-3,8:162.13
2,-3,8:161.5
3,-3,8:161.5
5,-3,8:161.13
3,-2,8:161.5
4,-2,8:161.5
5,-2,8:161.5
6,-2,8:161.13
7,-2,8:161.13
-4,-1,8:161.5
-3,-1,8:161.5
0,-1,8:161.5
3,-1,8:161.5
5,-1,8:161.5
-2,0,8:161.5
-1,0,8:161.5
0,0,8:162.13
1,0,8:161.5
6,0,8:161.13
-1,1,8:161.5
-2,2,8:161.5
3,2,8:161.5
0,3,8:161.5
1,-5,9:161.5
2,-5,9:161.5
-1,-4,9:161.5
1,-4,9:161.5
2,-4,9:161.5
3,-4,9:161.5
4,-4,9:161.5
-3,-3,9:161.5
-2,-3,9:161.5
2,-3,9:162.13
5,-3,9:161.13
-4,-2,9:161.5
1,-2,9:161.5
4,-2,9:161.5
5,-2,9:161.5
-1,-1,9:161.5
1,-1,9:161.5
3,-1,9:161.5
5,-1,9:161.5
-4,0,9:161.5
-1,0,9:162.13
1,0,9:162.13
2,0,9:161.5
-1,1,9:161.5
1,1,9:161.5
3,1,9:161.5
-2,2,9:161.5
-1,2,9:161.5
0,2,9:161.5
1,2,9:161.5
3,2,9:161.5
1,3,9:161.5
3,3,9:161.5
1,-6,10:161.5
2,-6,10:161.5
3,-6,10:161.5
0,-4,10:161.5
1,-4,10:161.5
2,-4,10:162.13
3,-4,10:161.5
2,-3,10:161.5
3,-3,10:161.5
4,-3,10:161.5
5,-3,10:161.13
0,-2,10:161.5
1,-2,10:161.5
2,-2,10:161.5
3,-2,10:162.13
4,-2,10:161.5
5,-2,10:161.5
-1,-1,10:161.5
2,-1,10:161.5
3,-1,10:161.5
4,-1,10:161.5
-2,0,10:161.5
1,0,10:162.13
2,0,10:161.5
3,0,10:161.5
4,0,10:161.5
-4,1,10:161.5
-2,1,10:162.13
-1,1,10:161.5
1,1,10:161.5
2,1,10:161.5
-4,2,10:161.5
-2,2,10:161.5
-1,2,10:161.5
0,2,10:161.5
1,2,10:161.5
3,2,10:161.5
-3,3,10:161.5
1,3,10:161.5
2,4,10:161.5
1,-6,11:161.5
2,-6,11:161.5
0,-5,11:161.5
1,-5,11:161.5
2,-5,11:161.5
0,-4,11:161.5
2,-4,11:162.13
4,-4,11:161.13
0,-3,11:161.5
2,-3,11:161.5
4,-3,11:161.5
1,-2,11:161.5
2,-2,11:161.5
5,-2,11:161.5
-1,-1,11:161.5
1,-1,11:161.5
0,0,11:161.5
2,0,11:161.5
-3,1,11:161.5
-2,1,11:161.5
-1,1,11:161.5
-3,2,11:161.5
-2,2,11:161.5
0,2,11:161.5
1,2,11:161.5
2,2,11:161.5
0,-4,12:161.5
2,-4,12:161.5
0,-3,12:161.13
1,-3,12:161.5
2,-2,12:161.5
2,-1,12:161.5
-2,2,12:161.5
1,-4,13:161.5
2,-4,13:161.5
