[META]
version=2.0
spawnOnBlockType=2,3
spawnSunlight=True
spawnDarkness=True
spawnWater=False
spawnLava=False
underFill=False
randomRotation=True
dig=True
tree=True
branch=False
needsFoundation=True
rarity=100
collisionPercentage=20
spawnElevationMin=0
spawnElevationMax=200
spawnInBiome=Custom
[DATA]
1,-4,-3:162.13
2,-2,-3:162.13
1,-4,-2:162.13
2,-3,-2:162.13
2,-2,-2:162.13
1,-4,-1:162.13
2,-3,-1:162.13
3,-3,-1:162.13
2,-2,-1:162.13
1,-4,0:162.13
2,-3,0:162.13
3,-3,0:162.13
2,-2,0:162.13
2,-3,1:162.13
2,-3,2:162.13
2,-3,3:162.13
2,-3,4:162.13
2,-3,5:162.13
2,-3,6:162.13
2,-3,7:162.13
2,-3,8:162.13
2,-3,9:162.13
2,-3,10:162.13
2,-3,11:162.13
2,-3,12:162.13
2,-3,13:162.13
2,-3,14:162.13
0,-3,15:162.13
1,-3,15:162.13
2,-3,15:162.13
0,-6,16:161.13
3,-4,16:162.13
-1,-3,16:162.13
2,-3,16:162.13
0,-7,17:161.13
-1,-6,17:161.13
-1,-5,17:161.13
0,-5,17:161.13
4,-5,17:162.13
-3,-4,17:161.13
-2,-4,17:161.13
1,-4,17:162.13
2,-4,17:161.13
-1,-3,17:162.13
2,-3,17:162.13
1,-2,17:162.13
2,-1,17:161.13
2,1,17:161.13
3,1,17:161.13
-1,-7,18:161.13
-2,-6,18:161.13
5,-6,18:161.13
6,-6,18:161.13
-2,-5,18:161.13
0,-5,18:162.13
1,-5,18:161.13
2,-5,18:161.13
4,-5,18:162.13
6,-5,18:161.13
-3,-4,18:161.13
-2,-4,18:161.13
-1,-4,18:161.13
0,-4,18:161.13
3,-4,18:161.13
5,-4,18:161.13
-4,-3,18:161.13
-2,-3,18:162.13
0,-3,18:161.13
2,-3,18:162.13
3,-3,18:162.13
4,-3,18:161.13
-2,-1,18:161.13
1,-1,18:162.13
2,-1,18:161.13
-2,-7,19:161.13
-1,-7,19:161.13
7,-7,19:161.13
-2,-6,19:161.13
-1,-6,19:161.13
2,-6,19:161.13
5,-6,19:162.13
6,-6,19:161.13
7,-6,19:161.13
-2,-5,19:161.13
-1,-5,19:162.13
0,-5,19:161.13
-1,-4,19:161.13
0,-4,19:161.13
3,-4,19:161.13
-4,-3,19:161.13
-2,-3,19:162.13
-1,-3,19:161.13
0,-3,19:161.13
2,-3,19:162.13
4,-3,19:162.13
6,-3,19:161.13
-3,-2,19:161.13
-1,-2,19:161.13
2,-2,19:161.13
4,-2,19:161.13
5,-2,19:161.13
-3,-1,19:161.13
-2,-1,19:161.13
0,-1,19:162.13
4,-1,19:161.13
-1,0,19:161.13
0,0,19:161.13
1,0,19:161.13
2,0,19:162.13
-2,1,19:161.13
0,1,19:161.13
1,1,19:161.13
3,1,19:161.13
2,2,19:161.13
6,-8,20:161.13
-2,-7,20:161.13
0,-7,20:161.13
3,-7,20:161.13
5,-7,20:161.13
-2,-6,20:162.13
4,-6,20:161.13
5,-6,20:162.13
6,-6,20:161.13
7,-6,20:161.13
-3,-5,20:161.13
-2,-5,20:161.13
-1,-5,20:161.13
0,-5,20:161.13
1,-5,20:161.13
4,-5,20:161.13
5,-5,20:161.13
-1,-4,20:161.13
1,-4,20:161.13
2,-4,20:161.13
4,-4,20:161.13
5,-4,20:161.13
-3,-3,20:161.13
-2,-3,20:161.13
-1,-3,20:161.13
0,-3,20:161.13
2,-3,20:162.13
3,-3,20:161.13
4,-3,20:162.13
5,-3,20:161.13
6,-3,20:161.13
1,-2,20:161.13
4,-2,20:161.13
-3,-1,20:161.13
-2,-1,20:161.13
-1,-1,20:162.13
1,-1,20:161.13
4,-1,20:161.13
-2,0,20:161.13
0,0,20:161.13
2,0,20:162.13
3,0,20:161.13
-2,1,20:161.13
1,1,20:161.13
3,1,20:161.13
4,1,20:161.13
5,1,20:161.13
5,2,20:161.13
3,3,20:161.13
4,3,20:161.13
-3,-7,21:161.13
-2,-6,21:162.13
-1,-6,21:161.13
0,-6,21:161.13
6,-6,21:161.13
7,-6,21:161.13
-3,-5,21:161.13
-2,-5,21:161.13
-1,-5,21:161.13
0,-5,21:161.13
2,-5,21:161.13
4,-5,21:161.13
5,-5,21:161.13
6,-5,21:161.13
7,-5,21:161.13
-4,-4,21:161.13
0,-4,21:161.13
1,-4,21:161.13
3,-4,21:161.13
4,-4,21:161.13
6,-4,21:161.13
-5,-3,21:161.13
-3,-3,21:161.13
-2,-3,21:161.13
-1,-3,21:161.13
2,-3,21:162.13
3,-3,21:161.13
4,-3,21:161.13
5,-3,21:162.13
6,-3,21:161.13
7,-3,21:161.13
-6,-2,21:161.13
-2,-2,21:161.13
-1,-2,21:161.13
1,-2,21:161.13
5,-2,21:161.13
8,-2,21:161.13
-6,-1,21:161.13
-4,-1,21:161.13
-2,-1,21:161.13
-1,-1,21:162.13
0,-1,21:161.13
3,-1,21:161.13
-3,0,21:161.13
-2,0,21:161.13
2,0,21:161.13
3,0,21:161.13
5,0,21:161.13
-4,1,21:161.13
-2,1,21:161.13
-1,1,21:161.13
2,1,21:161.13
3,1,21:162.13
4,1,21:161.13
2,3,21:161.13
3,3,21:161.13
-4,-8,22:161.13
2,-7,22:161.13
6,-7,22:161.13
-4,-6,22:161.13
-3,-6,22:162.13
-2,-6,22:161.13
-1,-6,22:161.13
0,-6,22:161.13
5,-6,22:161.13
-5,-5,22:161.13
-4,-5,22:161.13
-1,-5,22:161.13
0,-5,22:161.13
1,-5,22:161.13
2,-5,22:161.13
3,-5,22:161.13
5,-5,22:161.13
6,-5,22:161.13
-4,-4,22:161.13
-1,-4,22:161.13
2,-4,22:161.13
3,-4,22:161.13
5,-4,22:161.13
6,-4,22:161.13
-3,-3,22:161.13
2,-3,22:162.13
4,-3,22:161.13
5,-3,22:162.13
7,-3,22:161.13
-5,-2,22:161.13
-2,-2,22:161.13
4,-2,22:161.13
5,-2,22:161.13
6,-2,22:161.13
7,-2,22:161.13
9,-2,22:161.13
-2,-1,22:161.13
-1,-1,22:161.13
2,-1,22:161.13
6,-1,22:161.13
-6,0,22:161.13
-3,0,22:161.13
-1,0,22:162.13
0,0,22:161.13
-4,1,22:161.13
1,1,22:161.13
2,1,22:161.13
3,1,22:162.13
4,1,22:161.13
5,1,22:161.13
7,1,22:161.13
-4,2,22:161.13
-3,2,22:161.13
-2,2,22:161.13
-1,2,22:161.13
3,2,22:161.13
3,3,22:161.13
4,3,22:161.13
5,3,22:161.13
2,4,22:161.13
-4,-7,23:161.13
-3,-7,23:161.13
-1,-7,23:161.13
-5,-6,23:161.13
-3,-6,23:162.13
-1,-6,23:161.13
2,-6,23:161.13
-4,-5,23:161.13
-3,-5,23:161.13
-2,-5,23:161.13
-1,-5,23:161.13
1,-5,23:161.13
3,-5,23:161.13
5,-5,23:161.13
7,-5,23:161.13
-6,-4,23:161.13
-5,-4,23:161.13
-4,-4,23:161.13
-3,-4,23:161.13
0,-4,23:161.13
1,-4,23:161.13
2,-4,23:161.13
3,-4,23:162.13
5,-4,23:161.13
6,-4,23:161.13
-7,-3,23:161.13
-6,-3,23:161.13
-5,-3,23:161.13
0,-3,23:161.13
1,-3,23:162.13
2,-3,23:161.13
3,-3,23:161.13
5,-3,23:161.13
6,-3,23:162.13
7,-3,23:161.13
-6,-2,23:161.13
-5,-2,23:161.13
-4,-2,23:161.13
-3,-2,23:161.13
-2,-2,23:161.13
-1,-2,23:161.13
2,-2,23:161.13
7,-2,23:161.13
-7,-1,23:161.5
-4,-1,23:161.13
-2,-1,23:161.13
0,-1,23:161.13
4,-1,23:161.13
5,-1,23:161.13
6,-1,23:161.13
7,-1,23:161.13
-5,0,23:161.13
-4,0,23:161.13
-3,0,23:161.13
-2,0,23:162.13
-1,0,23:161.13
0,0,23:161.13
2,0,23:161.13
3,0,23:161.13
6,0,23:161.13
7,0,23:161.13
8,0,23:161.13
-6,1,23:161.13
-4,1,23:161.13
0,1,23:161.13
1,1,23:161.13
2,1,23:161.13
3,1,23:161.13
4,1,23:162.13
5,1,23:161.13
6,1,23:161.13
7,1,23:161.13
-4,2,23:161.13
-2,2,23:161.13
0,2,23:161.13
2,2,23:162.13
6,2,23:161.5
3,3,23:161.13
4,3,23:161.13
3,5,23:161.5
2,6,23:161.5
-3,-7,24:161.13
0,-7,24:161.13
-3,-6,24:161.13
-2,-6,24:161.13
-1,-6,24:161.13
2,-6,24:161.13
3,-6,24:161.13
6,-6,24:161.13
-5,-5,24:161.13
1,-5,24:161.13
2,-5,24:161.13
3,-5,24:161.13
4,-5,24:162.13
5,-5,24:161.13
-4,-4,24:161.13
-2,-4,24:161.13
-1,-4,24:161.13
0,-4,24:162.13
2,-4,24:161.13
3,-4,24:161.13
4,-4,24:161.13
-5,-3,24:161.13
-3,-3,24:161.13
3,-3,24:161.5
4,-3,24:161.13
6,-3,24:161.13
7,-3,24:161.13
-6,-2,24:161.13
-4,-2,24:161.13
0,-2,24:161.13
1,-2,24:161.13
5,-2,24:161.13
6,-2,24:161.13
7,-2,24:161.13
-5,-1,24:161.13
-4,-1,24:161.13
-1,-1,24:161.13
4,-1,24:161.13
5,-1,24:161.13
-2,0,24:161.13
-1,0,24:161.13
1,0,24:161.13
2,0,24:161.13
5,0,24:161.13
9,0,24:161.13
-4,1,24:161.13
-1,1,24:161.13
0,1,24:161.13
1,1,24:161.13
2,1,24:161.13
4,1,24:161.13
-5,2,24:161.13
-2,2,24:161.13
-1,2,24:161.13
0,2,24:161.13
1,2,24:161.13
2,2,24:162.13
4,2,24:161.5
6,2,24:161.5
1,3,24:161.13
2,3,24:161.13
3,3,24:161.13
4,3,24:161.5
5,3,24:161.5
0,4,24:161.13
1,4,24:161.13
1,5,24:161.5
1,6,24:161.5
-2,-7,25:161.13
-2,-6,25:161.13
0,-6,25:161.13
1,-6,25:161.13
2,-6,25:161.13
4,-6,25:161.13
-4,-5,25:161.13
-3,-5,25:161.13
-2,-5,25:161.13
0,-5,25:161.13
2,-5,25:161.13
4,-5,25:162.13
5,-5,25:161.5
6,-5,25:161.13
-2,-4,25:161.13
-1,-4,25:161.13
0,-4,25:162.13
1,-4,25:161.13
2,-4,25:161.13
3,-4,25:161.13
4,-4,25:161.5
7,-4,25:161.13
-3,-3,25:161.13
-2,-3,25:161.13
-1,-3,25:161.13
0,-3,25:161.13
2,-3,25:161.13
3,-3,25:161.13
4,-3,25:161.13
6,-3,25:161.13
-6,-2,25:161.13
1,-2,25:161.13
2,-2,25:161.13
3,-2,25:161.5
7,-2,25:161.13
8,-2,25:161.13
-5,-1,25:161.13
-3,-1,25:161.13
2,-1,25:161.13
-5,0,25:161.13
-2,0,25:161.13
-1,0,25:161.13
1,0,25:161.13
2,0,25:161.13
-3,1,25:161.13
2,1,25:161.13
3,1,25:161.13
4,1,25:161.13
0,2,25:161.13
1,2,25:161.13
2,2,25:161.13
3,2,25:161.13
4,2,25:161.5
-1,3,25:161.13
1,3,25:161.13
2,3,25:161.13
1,4,25:161.13
2,4,25:161.13
0,5,25:161.5
3,5,25:161.5
1,6,25:161.5
3,-7,26:161.13
4,-7,26:161.13
3,-6,26:161.5
2,-5,26:161.5
3,-5,26:161.5
5,-5,26:161.13
1,-4,26:161.13
2,-4,26:161.13
3,-4,26:161.13
-1,-3,26:161.13
1,-3,26:161.13
2,-3,26:161.5
3,-3,26:161.13
-1,-2,26:161.13
0,-2,26:161.13
1,-2,26:161.13
2,-2,26:161.13
3,-2,26:161.13
-1,-1,26:161.13
0,-1,26:161.13
1,-1,26:161.13
2,-1,26:161.13
1,0,26:161.13
1,1,26:161.13
2,1,26:161.13
2,2,26:161.13
3,3,26:161.13
2,-6,27:161.5
0,-4,27:161.13
3,-4,27:161.5
0,-3,27:161.13
2,-3,27:161.5
5,-3,27:161.5
0,-2,27:161.13
4,-2,27:161.5
0,-1,27:161.13
3,-1,27:161.13
2,-4,28:161.5
3,-4,28:161.5
4,-4,28:161.5
1,-3,28:161.13
3,-3,28:161.5
2,-2,28:161.13
