[META]
version=2.0
spawnOnBlockType=2,3
spawnSunlight=True
spawnDarkness=True
spawnWater=False
spawnLava=False
underFill=False
randomRotation=True
dig=True
tree=True
branch=False
needsFoundation=True
rarity=100
collisionPercentage=20
spawnElevationMin=0
spawnElevationMax=200
spawnInBiome=Custom
[DATA]
0,0,0:162.0
0,0,1:162.0
-1,-1,2:161.12
-3,0,2:161.12
0,0,2:162.12
0,2,2:161.12
2,2,2:161.12
1,3,2:161.12
-1,-3,3:161.12
4,-3,3:161.12
0,-2,3:161.12
-3,-1,3:161.12
-1,-1,3:161.12
-3,0,3:161.12
0,0,3:162.12
2,1,3:161.12
-1,2,3:161.12
0,2,3:161.12
2,2,3:161.12
1,3,3:161.12
3,3,3:161.12
2,4,3:161.12
-1,-3,4:161.12
0,-3,4:161.12
4,-3,4:161.12
-4,-2,4:161.12
0,-2,4:161.12
-3,-1,4:161.12
-1,-1,4:161.12
-3,0,4:161.12
0,0,4:162.12
2,1,4:161.12
-1,2,4:161.12
0,2,4:161.12
2,2,4:161.12
-1,3,4:161.12
1,3,4:161.12
3,3,4:161.12
0,4,4:161.12
2,4,4:161.12
3,4,4:161.12
3,-4,5:161.12
-3,-3,5:161.12
-1,-3,5:161.12
0,-3,5:161.12
1,-3,5:161.12
4,-3,5:161.12
-4,-2,5:161.12
-3,-2,5:162.12
-2,-2,5:161.12
-1,-2,5:162.12
0,-2,5:161.12
-3,-1,5:161.12
-2,-1,5:162.12
-1,0,5:162.12
0,0,5:162.12
-3,1,5:161.12
2,1,5:161.12
3,1,5:161.12
-2,2,5:161.12
-1,2,5:161.12
2,2,5:161.12
3,2,5:161.12
1,3,5:161.12
0,4,5:161.12
1,4,5:161.12
2,4,5:161.12
3,4,5:161.12
3,-4,6:161.12
2,-3,6:161.12
4,-3,6:161.12
-1,-2,6:161.12
4,-2,6:161.12
-3,0,6:161.12
0,0,6:162.12
-3,1,6:161.12
0,1,6:162.12
2,1,6:161.12
-1,2,6:161.12
1,2,6:162.12
2,2,6:161.12
3,2,6:161.12
0,3,6:162.12
1,3,6:161.12
2,3,6:162.12
-1,4,6:161.12
0,4,6:161.12
2,4,6:161.12
3,4,6:161.4
0,-3,7:161.12
1,-3,7:161.12
2,-3,7:161.12
3,-3,7:162.12
4,-3,7:161.12
-1,-2,7:161.12
1,-2,7:161.12
2,-2,7:162.12
4,-2,7:161.4
-2,-1,7:161.12
1,-1,7:162.12
-3,0,7:161.12
0,0,7:162.12
0,1,7:161.12
2,1,7:161.12
-3,2,7:161.12
-1,2,7:161.12
0,2,7:161.12
1,2,7:161.12
0,-3,8:161.12
3,-3,8:161.12
-1,-2,8:161.12
3,-2,8:161.12
-2,-1,8:161.12
-3,0,8:161.12
-2,0,8:162.12
-1,0,8:162.12
0,0,8:162.12
0,1,8:161.12
3,1,8:161.12
-3,2,8:161.12
-2,2,8:161.12
-1,2,8:161.12
1,2,8:161.12
1,-2,9:161.12
2,-2,9:161.12
2,-1,9:162.12
-1,0,9:161.12
0,0,9:162.12
1,0,9:162.12
-3,1,9:161.12
0,1,9:161.12
2,1,9:161.12
3,1,9:161.12
-3,2,9:161.12
-2,2,9:161.12
1,2,9:161.12
3,2,9:161.12
1,-1,10:161.12
2,-1,10:161.4
-2,0,10:161.12
0,0,10:162.12
1,0,10:161.12
-3,1,10:161.12
0,1,10:161.12
3,1,10:161.12
-3,2,10:161.12
-2,2,10:161.12
0,2,10:161.12
3,2,10:161.12
1,3,10:161.12
0,-3,11:161.12
-1,-2,11:161.12
1,-2,11:161.12
1,-1,11:161.12
-2,0,11:161.12
0,0,11:162.12
-3,1,11:161.12
1,1,11:162.12
2,1,11:161.12
-2,2,11:161.12
-1,2,11:161.12
0,2,11:161.12
1,2,11:161.12
2,2,11:162.12
1,3,11:161.12
-1,-2,12:161.12
1,-2,12:161.12
-2,0,12:161.12
-1,0,12:162.12
0,0,12:162.12
-3,1,12:161.12
-2,1,12:162.12
0,1,12:161.12
1,1,12:161.12
-2,2,12:161.12
-1,2,12:161.12
0,2,12:161.12
2,2,12:161.12
0,-3,13:161.12
-1,-2,13:161.12
1,-1,13:161.12
-1,0,13:161.12
0,0,13:162.12
-2,1,13:161.12
0,1,13:161.12
0,2,13:161.12
0,-3,14:161.12
-1,-2,14:161.12
0,-2,14:162.12
1,-2,14:161.12
0,-1,14:162.12
1,-1,14:161.12
-2,0,14:161.12
-1,0,14:161.12
0,0,14:162.12
2,0,14:161.12
-2,1,14:161.12
2,1,14:161.12
-1,2,14:161.12
0,-2,15:161.12
-2,-1,15:161.12
0,-1,15:161.12
1,-1,15:161.12
2,-1,15:161.12
-2,0,15:161.12
-1,0,15:161.12
0,0,15:162.12
-1,1,15:162.12
0,1,15:161.12
1,1,15:161.12
0,2,15:161.12
0,-2,16:161.12
-2,-1,16:161.12
0,-1,16:161.12
1,-1,16:161.12
2,-1,16:161.12
-2,0,16:161.12
-1,0,16:161.12
0,0,16:162.12
1,0,16:162.12
2,0,16:161.4
-1,1,16:161.12
1,1,16:161.12
0,-2,17:161.12
-2,-1,17:161.12
-1,-1,17:162.12
0,-1,17:161.12
-2,0,17:161.12
-1,0,17:161.12
0,0,17:162.12
-1,-1,18:161.12
0,0,18:162.12
0,-1,19:161.12
-1,0,19:161.12
0,0,19:162.12
1,0,19:161.12
0,1,19:161.12
-1,0,20:161.12
0,0,20:161.12
0,0,21:161.12
