[META]
version=2.0
spawnOnBlockType=2,3
spawnSunlight=True
spawnDarkness=True
spawnWater=False
spawnLava=False
underFill=False
randomRotation=True
dig=True
tree=True
branch=False
needsFoundation=True
rarity=100
collisionPercentage=20
spawnElevationMin=0
spawnElevationMax=200
spawnInBiome=Custom
[DATA]
-1,-1,-3:162.12
-1,-2,-2:162.12
-1,-1,-2:162.12
-3,0,-2:162.12
0,0,-2:162.12
-1,-2,-1:162.12
-2,-1,-1:162.12
-1,-1,-1:162.12
-3,0,-1:162.12
0,0,-1:162.12
-1,-2,0:162.12
-2,-1,0:162.12
-1,-1,0:162.12
0,-1,0:162.12
-3,0,0:162.12
0,0,0:162.12
-2,-1,1:162.12
-1,-1,1:162.12
-1,-1,2:162.12
-4,-5,3:161.12
-1,-5,3:161.12
-5,-4,3:161.12
-3,-4,3:161.12
-1,-4,3:161.12
-5,-3,3:161.12
-3,-3,3:161.12
-2,-3,3:161.12
0,-3,3:161.12
-5,-1,3:161.12
-4,-1,3:161.12
-1,-1,3:162.12
-6,0,3:161.12
-5,0,3:161.12
-4,0,3:161.12
-3,0,3:161.12
-2,0,3:161.12
1,0,3:161.12
-6,1,3:161.12
-4,1,3:161.12
-3,1,3:161.12
0,1,3:161.12
-4,-5,4:161.12
-2,-5,4:161.12
-1,-5,4:161.12
-6,-4,4:161.12
-4,-4,4:161.12
-3,-4,4:161.12
-1,-4,4:161.12
-5,-3,4:161.12
-4,-3,4:161.12
-3,-3,4:161.12
-2,-3,4:161.12
0,-3,4:161.12
-5,-2,4:161.12
-4,-2,4:162.12
-3,-2,4:161.12
-2,-2,4:161.12
-5,-1,4:161.12
-4,-1,4:161.12
-3,-1,4:162.12
-2,-1,4:162.12
-1,-1,4:162.12
-6,0,4:161.12
-5,0,4:161.12
-4,0,4:161.12
-2,0,4:161.12
1,0,4:161.12
-6,1,4:161.12
-4,1,4:161.12
-4,-6,5:161.12
-4,-5,5:161.12
-2,-5,5:161.12
-1,-5,5:161.12
-5,-4,5:161.12
-4,-4,5:161.12
-1,-4,5:161.12
-5,-3,5:162.12
-3,-3,5:161.12
-2,-3,5:161.12
0,-3,5:161.12
-1,-1,5:162.12
-6,0,5:161.12
-5,0,5:161.12
-4,0,5:162.12
1,0,5:161.12
2,0,5:161.12
4,0,5:161.4
-6,1,5:161.12
-5,1,5:162.12
1,1,5:161.12
1,2,5:161.12
3,2,5:161.12
1,3,5:161.12
2,3,5:161.12
-4,-6,6:161.12
-4,-5,6:161.12
-2,-5,6:161.12
-1,-5,6:161.12
-4,-4,6:161.12
-3,-4,6:161.12
-1,-4,6:161.12
-5,-3,6:161.12
-3,-3,6:161.12
-2,-3,6:161.12
0,-3,6:161.12
-2,-2,6:161.12
-1,-1,6:162.12
-4,0,6:161.12
0,0,6:162.12
2,0,6:161.12
-5,1,6:161.12
0,1,6:161.12
1,1,6:161.12
1,2,6:161.12
2,2,6:161.12
3,2,6:161.12
-4,-6,7:161.12
-4,-5,7:161.12
-3,-5,7:162.12
-2,-5,7:161.12
-1,-5,7:161.12
-4,-4,7:161.12
-3,-4,7:161.12
-2,-4,7:162.12
-1,-4,7:161.12
-3,-3,7:161.12
-2,-3,7:161.12
-1,-3,7:162.12
0,-3,7:161.12
-1,-2,7:162.12
-1,-1,7:162.12
2,0,7:161.12
3,0,7:161.12
1,1,7:161.12
2,1,7:162.12
3,1,7:162.12
4,1,7:161.4
2,2,7:162.12
3,2,7:161.12
1,3,7:161.12
0,-6,8:161.12
1,-6,8:161.12
-4,-5,8:161.12
-3,-5,8:161.12
0,-5,8:161.12
1,-5,8:161.12
2,-5,8:161.12
-3,-4,8:161.12
-2,-4,8:161.12
0,-4,8:161.12
3,-4,8:161.12
-5,-3,8:161.12
-4,-3,8:161.12
-1,-3,8:161.12
0,-3,8:161.12
2,-3,8:161.12
1,-2,8:161.12
2,-2,8:161.12
-1,-1,8:162.12
0,1,8:161.12
1,1,8:161.12
2,1,8:161.12
3,1,8:161.12
-1,2,8:161.12
1,2,8:161.12
2,2,8:161.12
-2,3,8:161.12
0,3,8:161.12
0,-6,9:161.12
1,-6,9:161.12
-4,-5,9:161.12
1,-5,9:161.12
2,-5,9:161.12
-3,-4,9:161.12
0,-4,9:161.12
1,-4,9:161.12
3,-4,9:161.12
-5,-3,9:161.12
0,-3,9:161.12
2,-3,9:161.12
4,-3,9:161.4
1,-2,9:161.12
2,-2,9:161.12
-1,-1,9:162.12
1,1,9:161.12
-1,2,9:161.12
1,2,9:161.12
-2,3,9:161.12
0,-6,10:161.12
1,-6,10:161.12
2,-6,10:161.12
-4,-5,10:161.12
0,-5,10:161.12
1,-5,10:161.12
2,-5,10:161.12
-3,-4,10:161.4
0,-4,10:161.12
3,-4,10:161.12
-5,-3,10:161.12
0,-3,10:161.12
2,-3,10:161.12
1,-2,10:161.12
2,-2,10:161.12
-1,-1,10:162.12
-3,1,10:161.4
0,1,10:161.12
1,1,10:161.12
-1,2,10:161.12
1,2,10:161.12
-2,3,10:161.12
0,3,10:161.12
-6,-6,11:161.12
-4,-6,11:161.12
0,-6,11:161.12
1,-6,11:161.12
-4,-5,11:161.12
0,-5,11:161.12
1,-5,11:161.12
2,-5,11:161.12
3,-5,11:161.12
-5,-4,11:161.12
0,-4,11:161.12
1,-4,11:161.12
3,-4,11:161.12
-5,-3,11:161.12
-4,-3,11:161.12
0,-3,11:161.12
2,-3,11:161.12
4,-3,11:161.12
1,-2,11:161.12
-1,-1,11:162.12
0,1,11:161.12
1,1,11:161.12
-1,2,11:161.12
1,2,11:161.12
-2,3,11:161.12
0,3,11:161.12
-6,-6,12:161.12
-4,-6,12:161.12
0,-6,12:161.12
1,-6,12:161.12
2,-6,12:161.12
-6,-5,12:161.12
-4,-5,12:161.12
0,-5,12:161.12
1,-5,12:161.12
2,-5,12:162.12
3,-5,12:161.12
-5,-4,12:161.12
-3,-4,12:161.12
0,-4,12:161.12
2,-4,12:162.12
3,-4,12:161.12
-5,-3,12:161.12
0,-3,12:161.12
1,-3,12:162.12
2,-3,12:161.12
3,-3,12:162.12
4,-3,12:161.4
0,-2,12:162.12
-1,-1,12:162.12
0,0,12:161.12
-3,1,12:161.12
0,1,12:161.12
1,1,12:161.12
-1,2,12:161.12
0,3,12:161.12
2,3,12:161.4
-4,4,12:161.12
0,4,12:161.12
-6,-6,13:161.12
-5,-6,13:161.12
-4,-6,13:161.4
1,-6,13:161.12
-6,-5,13:161.12
1,-5,13:161.12
-4,-4,13:161.12
-3,-4,13:161.12
2,-4,13:161.12
-5,-3,13:161.12
0,-3,13:161.12
2,-3,13:161.12
3,-3,13:161.4
-3,-2,13:161.12
0,-2,13:161.4
1,-2,13:161.12
-4,-1,13:161.12
-1,-1,13:162.12
-3,0,13:161.12
0,0,13:161.12
-3,1,13:161.12
1,1,13:161.12
-5,2,13:161.12
-4,2,13:161.12
-1,2,13:161.12
1,2,13:161.12
-3,3,13:161.12
-4,4,13:161.12
0,4,13:161.12
1,4,13:161.12
-6,-6,14:161.12
-5,-6,14:161.12
1,-6,14:161.12
-6,-5,14:161.12
-5,-5,14:17.4
1,-5,14:161.12
-5,-4,14:161.12
-3,-4,14:161.12
-5,-3,14:161.12
-4,-3,14:161.12
-3,-3,14:162.12
0,-3,14:161.12
2,-3,14:161.12
-3,-2,14:161.12
-2,-2,14:162.12
1,-2,14:161.12
-4,-1,14:161.12
-1,-1,14:162.12
-3,0,14:161.12
0,0,14:161.12
1,1,14:161.12
-5,2,14:161.12
-4,2,14:161.12
-1,2,14:161.12
1,2,14:161.12
-3,3,14:161.12
-2,3,14:161.12
0,3,14:161.12
-4,4,14:161.12
0,4,14:161.12
1,4,14:161.12
1,-6,15:161.12
2,-6,15:161.12
3,-6,15:161.12
-5,-5,15:161.12
1,-5,15:161.12
3,-5,15:161.12
-4,-4,15:161.12
2,-4,15:161.12
3,-4,15:161.12
-3,-3,15:161.12
0,-3,15:161.12
2,-3,15:161.12
-3,-2,15:161.12
1,-2,15:161.12
-4,-1,15:161.12
-1,-1,15:162.12
-3,0,15:161.4
-1,0,15:162.12
0,0,15:161.12
-1,1,15:162.12
0,1,15:161.12
1,1,15:161.4
-4,2,15:161.12
-3,2,15:162.12
-2,2,15:162.12
-1,2,15:161.12
0,2,15:162.12
-5,3,15:161.12
-4,3,15:162.12
-3,3,15:161.12
-2,3,15:161.12
1,3,15:162.12
-5,4,15:161.12
-4,4,15:161.12
0,4,15:161.12
1,4,15:161.4
1,-6,16:161.12
3,-6,16:161.12
1,-5,16:161.12
3,-5,16:161.12
2,-4,16:161.12
0,-3,16:161.12
2,-3,16:161.12
-3,-2,16:161.4
1,-2,16:161.12
-4,-1,16:161.12
-3,-1,16:17.4
-2,-1,16:17.4
-1,-1,16:162.12
0,0,16:161.12
-3,2,16:161.4
0,2,16:161.4
-4,3,16:161.4
1,3,16:161.4
1,-6,17:161.12
1,-5,17:161.12
2,-5,17:162.12
3,-5,17:161.12
-5,-4,17:161.12
-4,-4,17:161.12
1,-4,17:162.12
2,-4,17:161.12
3,-4,17:161.4
0,-3,17:161.12
1,-3,17:162.12
-5,-2,17:161.12
0,-2,17:162.12
-3,-1,17:161.4
-1,-1,17:162.12
-2,0,17:161.12
-3,1,17:161.12
0,1,17:161.12
-3,2,17:161.12
0,2,17:161.12
-3,3,17:161.12
-1,-5,18:161.12
-5,-4,18:161.12
-4,-4,18:161.4
0,-3,18:161.12
2,-3,18:161.12
-5,-2,18:161.12
-4,-2,18:161.12
-3,-2,18:161.12
1,-2,18:161.12
-1,-1,18:162.12
3,-1,18:161.12
-5,0,18:161.12
0,0,18:161.12
1,0,18:161.12
2,0,18:161.12
-3,1,18:161.12
-2,1,18:161.12
0,1,18:161.12
-5,2,18:161.12
-4,2,18:161.12
-3,2,18:161.12
-1,2,18:161.12
0,2,18:161.12
-3,3,18:161.12
-2,3,18:161.12
-1,3,18:161.12
-1,-5,19:161.12
-5,-4,19:161.12
-5,-3,19:161.12
1,-3,19:161.12
2,-3,19:161.12
-5,-2,19:161.12
-4,-2,19:161.12
-3,-2,19:161.4
1,-2,19:161.12
-1,-1,19:162.12
3,-1,19:161.12
-5,0,19:161.12
-4,0,19:161.12
-2,0,19:161.12
-1,0,19:162.12
0,0,19:161.12
-3,1,19:161.12
-2,1,19:161.12
-1,1,19:162.12
0,1,19:161.12
-5,2,19:161.12
-4,2,19:161.12
-3,2,19:161.12
-2,2,19:162.12
0,2,19:161.4
-3,3,19:161.12
-1,3,19:161.12
-4,-4,20:161.4
-2,-4,20:161.12
0,-4,20:161.12
-4,-3,20:162.12
-3,-3,20:162.12
0,-3,20:161.12
2,-3,20:161.12
-5,-2,20:161.12
-4,-2,20:161.12
-2,-2,20:162.12
1,-2,20:161.12
-1,-1,20:162.12
3,-1,20:161.12
-5,0,20:161.12
0,0,20:161.12
1,0,20:161.12
-2,1,20:161.12
-5,2,20:161.12
-4,2,20:161.12
-1,2,20:161.12
-3,3,20:161.12
-2,3,20:161.12
-1,-5,21:161.12
0,-4,21:161.12
-4,-3,21:161.4
-3,-3,21:161.4
0,-3,21:161.12
1,-3,21:161.12
2,-3,21:161.12
-2,-2,21:161.4
1,-2,21:161.12
3,-2,21:161.12
-1,-1,21:162.12
3,-1,21:161.12
-5,0,21:161.12
-4,0,21:161.4
0,0,21:161.12
1,0,21:161.12
2,0,21:161.12
-2,1,21:161.12
-5,2,21:161.12
-3,2,21:161.12
-1,2,21:161.12
-1,3,21:161.12
-1,-5,22:161.12
-2,-4,22:161.12
-1,-4,22:162.12
-1,-3,22:162.12
2,-3,22:161.12
-1,-2,22:162.12
2,-2,22:162.12
3,-2,22:161.12
-1,-1,22:162.12
0,-1,22:162.12
1,-1,22:162.12
2,-1,22:161.12
3,-1,22:161.4
-5,0,22:161.12
1,0,22:161.12
2,0,22:161.12
-2,1,22:161.12
-5,2,22:161.12
-4,2,22:161.12
-3,2,22:161.12
-1,2,22:161.12
-3,3,22:161.12
-2,3,22:161.12
-1,-4,23:161.12
1,-4,23:161.12
-1,-3,23:161.12
2,-3,23:161.12
-4,-2,23:161.12
-3,-2,23:161.4
2,-2,23:161.12
-4,-1,23:161.12
-1,-1,23:162.12
-5,0,23:161.12
-4,0,23:161.12
-3,0,23:161.12
-2,0,23:162.12
-4,1,23:162.12
-3,1,23:162.12
-2,1,23:161.12
-5,2,23:161.12
-3,2,23:161.12
-2,2,23:162.12
-1,2,23:161.4
-2,3,23:161.12
1,-4,24:161.12
0,-3,24:161.12
-4,-2,24:161.12
2,-2,24:161.12
-4,-1,24:161.12
-1,-1,24:162.12
-2,0,24:161.12
1,-3,25:162.12
2,-3,25:161.12
-4,-2,25:161.12
-3,-2,25:161.4
0,-2,25:162.12
2,-2,25:161.12
-4,-1,25:161.12
-1,-1,25:162.12
-4,0,25:161.12
-3,0,25:161.12
-2,0,25:161.12
2,-4,26:161.12
0,-3,26:161.12
1,-3,26:161.4
-4,-2,26:161.12
0,-2,26:161.4
1,-2,26:161.12
2,-2,26:161.12
-4,-1,26:161.12
-3,-1,26:162.12
-2,-1,26:162.12
-1,-1,26:162.12
-4,0,26:161.12
-3,0,26:161.12
-2,0,26:161.4
2,-4,27:161.12
2,-3,27:161.12
1,-2,27:161.12
-3,-1,27:161.4
-2,-1,27:161.4
-1,-1,27:162.12
1,-4,28:161.4
2,-4,28:161.12
0,-3,28:161.12
1,-3,28:162.12
2,-3,28:161.4
0,-2,28:162.12
1,-2,28:161.12
-1,-1,28:162.12
0,0,28:161.12
-2,1,28:161.12
0,1,28:161.12
-1,2,28:161.12
-3,-3,29:161.12
-2,-3,29:161.12
1,-3,29:161.4
-2,-2,29:161.12
0,-2,29:161.4
-4,-1,29:161.12
-1,-1,29:162.12
-1,0,29:162.12
0,0,29:161.12
-2,1,29:161.12
-1,1,29:162.12
0,1,29:161.4
-2,2,29:161.12
-1,2,29:161.4
-3,-3,30:161.12
-4,-2,30:161.12
-2,-2,30:161.12
-4,-1,30:161.12
-3,-1,30:161.12
-1,-1,30:162.12
-1,0,30:161.4
-1,1,30:161.4
-3,-3,31:161.12
-2,-3,31:161.12
-3,-2,31:162.12
-2,-2,31:161.4
-4,-1,31:161.12
-3,-1,31:161.12
-2,-1,31:162.12
-1,-1,31:162.12
-3,-2,32:161.4
-2,-1,32:161.4
-1,-1,32:162.12
-1,0,32:161.12
-1,-1,33:162.12
-1,0,33:161.12
1,0,33:161.12
0,1,33:161.12
0,-3,34:161.12
-3,-2,34:161.12
-2,-2,34:161.12
-1,-2,34:161.12
1,-2,34:161.12
-1,-1,34:162.12
0,-1,34:161.12
-3,0,34:161.4
-1,0,34:161.12
0,0,34:162.12
1,0,34:161.4
0,1,34:161.12
-1,-3,35:161.12
0,-3,35:161.12
-3,-2,35:161.12
-2,-2,35:161.12
-1,-2,35:161.12
1,-2,35:161.12
-2,-1,35:162.12
-1,-1,35:162.12
0,-1,35:161.12
-1,0,35:161.12
-1,-3,36:161.12
0,-3,36:161.12
-1,-2,36:161.12
0,-2,36:162.12
1,-2,36:161.4
-2,-1,36:161.4
-1,-1,36:162.12
0,-1,36:161.12
-1,-2,37:161.12
-2,-1,37:161.12
-1,-1,37:162.12
-1,-1,38:161.12
0,-1,38:161.4
-1,0,38:161.12
-1,-1,39:161.12
-1,-1,40:161.4
