[META]
version=2.0
spawnOnBlockType=2,3
spawnSunlight=True
spawnDarkness=True
spawnWater=False
spawnLava=False
underFill=False
randomRotation=True
dig=True
tree=True
branch=False
needsFoundation=True
rarity=100
collisionPercentage=20
spawnElevationMin=0
spawnElevationMax=200
spawnInBiome=Custom
[DATA]
1,-2,-3:162.13
3,-1,-3:162.13
0,0,-3:162.13
1,-2,-2:162.13
2,-2,-2:162.13
1,-1,-2:162.13
3,-1,-2:162.13
0,0,-2:162.13
1,-3,-1:162.13
1,-2,-1:162.13
2,-2,-1:162.13
1,-1,-1:162.13
2,-1,-1:162.13
3,-1,-1:162.13
0,0,-1:162.13
1,-3,0:162.13
1,-2,0:162.13
2,-2,0:162.13
1,-1,0:162.13
2,-1,0:162.13
3,-1,0:162.13
0,0,0:162.13
1,-2,1:162.13
2,-2,1:162.13
1,-1,1:162.13
2,-1,1:162.13
1,-2,2:162.13
2,-2,2:162.13
1,-1,2:162.13
2,-1,2:162.13
1,-2,3:162.13
2,-2,3:162.13
1,-1,3:162.13
2,-1,3:162.13
1,-2,4:162.13
2,-2,4:162.13
-2,-1,4:161.13
0,-1,4:161.13
1,-1,4:162.13
2,-1,4:162.13
-1,0,4:161.13
-2,-3,5:161.13
-1,-2,5:161.13
1,-2,5:162.13
2,-2,5:162.13
-2,-1,5:161.13
1,-1,5:162.13
2,-1,5:162.13
5,0,5:161.13
5,-4,6:161.13
3,-3,6:161.13
7,-3,6:161.13
-3,-2,6:161.13
-1,-2,6:161.13
1,-2,6:162.13
2,-2,6:162.13
8,-2,6:161.13
-4,-1,6:161.13
-1,-1,6:161.13
0,-1,6:162.13
1,-1,6:162.13
2,-1,6:162.13
4,-1,6:161.13
1,0,6:161.13
5,2,6:161.13
2,4,6:161.13
3,4,6:161.13
3,-4,7:161.13
8,-4,7:161.13
0,-3,7:161.13
2,-3,7:161.13
5,-3,7:161.13
8,-3,7:161.13
9,-3,7:161.13
-1,-2,7:161.13
1,-2,7:162.13
2,-2,7:162.13
5,-2,7:161.13
-3,-1,7:161.13
-1,-1,7:162.13
0,-1,7:162.13
1,-1,7:162.13
2,-1,7:162.13
-5,0,7:161.13
1,0,7:162.13
5,0,7:161.13
7,0,7:161.13
-3,1,7:161.13
-1,1,7:161.13
5,2,7:161.13
4,3,7:161.13
4,4,7:161.13
0,5,7:161.5
1,7,7:161.13
5,-6,8:161.13
-1,-4,8:161.13
8,-3,8:161.13
-6,-2,8:161.13
-1,-2,8:161.13
1,-2,8:162.13
2,-2,8:162.13
-4,-1,8:161.13
-3,-1,8:161.13
-2,-1,8:162.13
1,-1,8:162.13
2,-1,8:162.13
-3,0,8:161.13
5,0,8:161.13
6,0,8:161.13
-5,1,8:161.13
1,1,8:162.13
2,1,8:161.13
3,1,8:161.13
6,1,8:161.13
4,2,8:161.13
2,3,8:161.13
3,3,8:161.13
5,3,8:161.13
7,3,8:161.13
-7,4,8:161.13
-6,4,8:161.13
5,4,8:161.13
3,7,8:161.13
4,7,8:161.13
5,-6,9:161.13
3,-4,9:161.13
6,-4,9:161.13
-2,-3,9:161.13
-1,-3,9:161.13
0,-3,9:162.13
2,-3,9:161.13
3,-3,9:161.13
4,-3,9:161.13
5,-3,9:161.13
7,-3,9:161.13
8,-3,9:161.13
-3,-2,9:161.13
0,-2,9:161.13
2,-2,9:162.13
-4,-1,9:161.13
-2,-1,9:161.13
1,-1,9:162.13
2,-1,9:162.13
3,-1,9:161.13
5,-1,9:161.13
6,-1,9:161.13
8,-1,9:161.13
-7,0,9:161.13
-3,0,9:162.13
-2,0,9:161.13
-1,0,9:161.13
7,0,9:161.13
-4,1,9:161.13
4,1,9:161.13
5,1,9:161.13
7,1,9:161.13
8,1,9:161.13
-4,2,9:161.13
1,2,9:162.13
5,2,9:161.13
1,3,9:161.13
2,3,9:161.13
4,3,9:161.13
5,3,9:161.13
-6,4,9:161.13
3,4,9:161.13
5,4,9:161.13
-6,5,9:161.13
0,5,9:161.13
1,5,9:161.13
3,5,9:161.13
4,5,9:161.13
6,5,9:161.13
-4,6,9:161.13
0,6,9:161.13
2,6,9:161.13
4,6,9:161.13
-3,7,9:161.13
0,7,9:161.13
1,7,9:161.13
2,7,9:161.13
2,8,9:161.13
6,-6,10:161.13
4,-5,10:161.13
5,-5,10:161.13
-6,-4,10:161.13
-2,-4,10:161.13
0,-4,10:161.13
1,-4,10:161.13
6,-4,10:161.13
-6,-3,10:161.13
-3,-3,10:161.13
-2,-3,10:161.13
0,-3,10:162.13
2,-3,10:161.13
3,-3,10:161.13
5,-3,10:161.13
7,-3,10:161.13
8,-3,10:161.13
-3,-2,10:161.13
2,-2,10:161.13
3,-2,10:162.13
5,-2,10:161.13
6,-2,10:161.13
8,-2,10:161.13
-7,-1,10:161.13
-4,-1,10:161.13
-3,-1,10:161.13
1,-1,10:162.13
4,-1,10:161.13
6,-1,10:161.13
-7,0,10:161.13
-5,0,10:161.13
-4,0,10:162.13
-1,0,10:161.13
0,0,10:161.13
1,0,10:161.13
3,0,10:162.13
5,0,10:161.13
-5,1,10:161.13
-4,1,10:161.13
-6,2,10:161.13
1,2,10:162.13
2,2,10:161.13
-6,3,10:161.13
1,3,10:161.13
5,3,10:161.13
-4,4,10:161.13
1,4,10:161.13
2,4,10:161.13
3,4,10:161.13
4,4,10:161.13
5,4,10:161.13
-4,5,10:161.13
-1,5,10:161.13
0,5,10:161.13
1,5,10:161.13
2,5,10:161.13
-8,6,10:161.13
-5,6,10:161.13
0,6,10:161.13
4,6,10:161.13
-6,7,10:161.13
-4,8,10:161.13
-3,8,10:161.13
-6,-10,11:161.13
5,-9,11:161.13
3,-8,11:161.13
4,-7,11:161.13
0,-6,11:161.13
3,-6,11:161.13
5,-6,11:161.13
0,-5,11:161.13
2,-5,11:161.13
3,-5,11:161.13
5,-5,11:161.13
-2,-4,11:161.13
2,-4,11:161.13
-5,-3,11:161.13
0,-3,11:162.13
2,-3,11:161.13
4,-3,11:161.13
7,-3,11:161.13
-7,-2,11:161.13
2,-2,11:161.13
3,-2,11:162.13
4,-2,11:161.13
5,-2,11:161.13
2,-1,11:161.13
-7,0,11:161.13
-6,0,11:161.13
1,0,11:162.13
3,0,11:162.13
5,0,11:161.13
-6,1,11:161.13
-5,1,11:162.13
-2,1,11:161.13
3,1,11:161.13
4,1,11:161.13
7,1,11:161.13
-8,2,11:161.13
-4,2,11:161.13
-2,2,11:161.13
1,2,11:161.13
4,2,11:161.13
-9,3,11:161.13
-4,3,11:161.13
-3,3,11:161.13
-2,3,11:161.13
2,3,11:162.13
-6,4,11:161.13
-5,4,11:161.13
0,4,11:161.13
2,4,11:161.13
5,4,11:161.13
-9,5,11:161.13
-7,5,11:161.13
-3,5,11:161.13
-8,6,11:161.13
-6,6,11:161.13
-5,7,11:161.13
-3,7,11:161.13
1,7,11:161.13
3,7,11:161.13
-6,8,11:161.13
-5,8,11:161.13
-1,8,11:161.13
-5,-11,12:161.13
3,-11,12:161.13
-6,-10,12:161.13
-5,-10,12:161.13
3,-10,12:161.13
-4,-9,12:161.13
3,-9,12:161.13
-7,-8,12:161.13
-4,-8,12:161.13
1,-8,12:161.13
3,-8,12:161.13
6,-8,12:161.13
-6,-7,12:161.13
-5,-7,12:161.13
3,-7,12:161.13
-7,-6,12:161.13
3,-6,12:161.13
4,-6,12:161.13
6,-6,12:161.13
-6,-5,12:161.13
-2,-5,12:161.13
-1,-5,12:161.13
1,-5,12:161.13
4,-5,12:161.13
5,-5,12:161.13
6,-5,12:161.13
7,-5,12:161.13
-4,-4,12:161.13
-2,-4,12:161.13
0,-4,12:161.13
8,-4,12:161.5
-6,-3,12:161.13
-1,-3,12:162.13
0,-3,12:161.13
1,-3,12:161.13
4,-3,12:162.13
0,-1,12:161.13
2,-1,12:161.13
-9,0,12:161.13
-8,0,12:161.13
-5,0,12:161.13
-2,0,12:161.5
1,0,12:162.13
3,0,12:161.13
7,0,12:161.13
-9,1,12:161.13
-6,1,12:161.13
-5,1,12:162.13
1,1,12:161.13
4,1,12:162.13
5,1,12:161.13
7,1,12:161.13
-8,2,12:161.13
-7,2,12:161.13
-6,2,12:161.13
-5,2,12:161.13
-3,2,12:161.13
-2,2,12:161.13
2,2,12:161.13
4,2,12:161.13
6,2,12:161.13
-8,3,12:161.13
-5,3,12:161.13
2,3,12:161.13
-1,4,12:161.13
2,4,12:162.13
3,4,12:161.13
4,4,12:161.13
-7,5,12:161.13
-4,5,12:161.13
-1,5,12:161.13
0,5,12:161.13
1,5,12:161.13
3,5,12:161.13
-8,6,12:161.13
-4,6,12:161.13
-1,6,12:161.13
0,6,12:161.13
1,6,12:161.13
-6,7,12:161.13
-5,7,12:161.13
-1,7,12:161.13
3,7,12:161.13
-4,8,12:161.13
-2,8,12:161.13
-5,9,12:161.13
5,-11,13:161.13
-5,-10,13:161.13
-4,-10,13:161.13
1,-10,13:161.13
5,-10,13:161.13
-4,-9,13:161.13
-3,-9,13:161.13
0,-9,13:161.13
5,-9,13:161.13
6,-9,13:161.13
-7,-8,13:161.13
-4,-8,13:161.13
-3,-8,13:161.13
1,-8,13:161.13
6,-8,13:161.13
5,-7,13:161.13
-6,-6,13:161.13
-3,-6,13:161.13
6,-6,13:161.13
7,-6,13:161.13
-6,-5,13:161.13
3,-5,13:161.13
4,-5,13:161.13
-6,-4,13:161.13
-3,-4,13:161.13
2,-4,13:161.13
4,-4,13:161.13
5,-4,13:162.13
6,-4,13:161.13
-1,-3,13:162.13
0,-3,13:161.13
4,-3,13:162.13
5,-3,13:161.13
-7,-2,13:161.13
-1,-2,13:161.13
0,-2,13:161.13
4,-2,13:161.13
5,-2,13:161.13
6,-2,13:161.13
-5,-1,13:161.13
4,-1,13:161.13
-10,0,13:161.13
-5,0,13:161.13
-3,0,13:161.13
0,0,13:162.13
2,0,13:161.13
-10,1,13:161.13
-6,1,13:162.13
-3,1,13:161.13
2,1,13:161.13
4,1,13:162.13
-5,2,13:161.13
-1,2,13:161.13
-7,3,13:161.13
-1,3,13:161.13
1,3,13:161.13
2,3,13:161.13
4,3,13:161.13
6,3,13:161.13
-5,4,13:161.13
-1,4,13:161.13
1,4,13:161.13
1,5,13:162.13
-4,6,13:161.13
-3,6,13:161.13
-1,6,13:161.13
0,6,13:161.13
-1,8,13:161.13
1,8,13:161.13
2,8,13:161.13
3,8,13:161.5
-4,9,13:161.13
-4,-11,14:161.13
1,-11,14:161.13
2,-11,14:161.13
3,-11,14:161.13
4,-11,14:161.13
-6,-10,14:161.13
-6,-9,14:161.13
0,-9,14:161.13
1,-9,14:161.13
2,-9,14:161.13
-6,-8,14:161.13
-3,-8,14:161.13
2,-7,14:161.13
3,-7,14:161.13
4,-7,14:161.13
5,-7,14:161.13
7,-7,14:161.13
8,-6,14:161.13
-3,-5,14:161.13
2,-5,14:161.13
6,-5,14:162.13
7,-5,14:161.13
7,-4,14:161.13
-7,-3,14:161.13
-3,-3,14:161.13
-1,-3,14:162.13
4,-3,14:162.13
8,-3,14:161.5
-8,-2,14:161.13
-7,-2,14:161.13
3,-2,14:161.13
7,-2,14:161.13
-10,-1,14:161.13
-8,-1,14:161.13
-6,-1,14:161.13
-5,-1,14:161.13
-4,-1,14:161.13
-1,-1,14:161.13
4,-1,14:161.13
6,-1,14:161.13
-8,0,14:161.13
-7,0,14:162.13
0,0,14:162.13
3,0,14:161.13
6,0,14:161.13
-7,1,14:161.13
-6,1,14:162.13
0,1,14:162.13
4,1,14:162.13
0,2,14:162.13
4,2,14:161.13
-8,3,14:161.13
-5,3,14:161.13
-2,3,14:161.13
1,3,14:161.13
2,3,14:161.13
5,3,14:161.13
-8,4,14:161.13
1,4,14:161.13
-8,5,14:161.13
-7,5,14:161.13
-5,5,14:161.13
2,5,14:161.13
-4,6,14:161.13
-3,6,14:161.13
-2,6,14:161.13
1,6,14:162.13
4,6,14:161.13
-6,8,14:161.13
-4,8,14:161.13
-3,9,14:161.13
-4,-11,15:161.13
1,-11,15:161.13
-4,-10,15:161.13
-2,-10,15:161.13
6,-10,15:161.13
-7,-9,15:161.13
-6,-9,15:161.13
-4,-9,15:161.13
-3,-9,15:161.13
2,-9,15:161.13
4,-9,15:161.13
-5,-8,15:161.13
-3,-8,15:161.13
3,-8,15:161.13
5,-8,15:161.13
6,-8,15:161.13
-5,-6,15:161.13
-4,-6,15:161.13
0,-6,15:161.13
5,-6,15:162.13
7,-6,15:161.13
9,-6,15:161.13
-5,-5,15:161.13
-1,-5,15:161.13
0,-5,15:161.13
1,-5,15:161.13
4,-5,15:161.13
6,-5,15:162.13
-2,-4,15:161.13
-1,-4,15:162.13
1,-4,15:161.13
2,-4,15:161.13
6,-4,15:161.13
-8,-3,15:161.13
0,-3,15:161.13
1,-3,15:161.13
2,-3,15:161.13
5,-3,15:162.13
-8,-2,15:161.13
-6,-2,15:161.13
-10,-1,15:161.13
-8,-1,15:162.13
-1,-1,15:161.13
-7,0,15:161.13
-4,0,15:161.5
0,0,15:162.13
4,0,15:161.13
5,0,15:161.13
6,0,15:161.13
8,0,15:161.13
5,1,15:162.13
6,1,15:161.13
8,1,15:161.13
-7,2,15:162.13
-6,2,15:161.13
3,2,15:162.13
8,2,15:161.13
-1,3,15:162.13
1,3,15:161.13
2,3,15:161.13
3,3,15:161.13
4,3,15:161.13
6,3,15:161.13
8,3,15:161.13
-8,4,15:161.13
-7,4,15:161.13
1,4,15:161.13
2,4,15:161.13
7,4,15:161.13
-9,5,15:161.13
-8,5,15:161.13
-7,5,15:161.13
-5,5,15:161.13
-1,5,15:161.13
0,5,15:161.13
1,5,15:161.13
2,5,15:161.13
8,5,15:161.13
-4,6,15:161.13
1,6,15:162.13
3,6,15:161.13
4,6,15:161.13
-7,7,15:161.13
-6,7,15:161.13
-4,7,15:161.13
4,7,15:161.13
6,7,15:161.13
-6,8,15:161.13
0,8,15:161.13
-6,9,15:161.13
-5,9,15:161.13
-2,9,15:161.13
1,9,15:161.13
-4,-10,16:161.13
-4,-9,16:161.13
6,-9,16:161.13
-7,-8,16:161.13
-4,-8,16:161.13
7,-8,16:161.13
-6,-7,16:161.13
-4,-7,16:161.13
4,-7,16:162.13
-2,-6,16:161.13
-1,-6,16:161.13
5,-6,16:161.13
7,-6,16:162.13
-2,-5,16:161.13
4,-5,16:161.13
8,-5,16:161.13
9,-5,16:161.13
-1,-4,16:162.13
2,-4,16:161.13
5,-4,16:161.13
-10,-3,16:161.13
-3,-3,16:161.13
5,-3,16:162.13
-8,-2,16:161.13
6,-2,16:161.13
8,-2,16:161.13
-8,-1,16:162.13
-5,-1,16:161.13
-10,0,16:161.13
6,0,16:162.13
8,0,16:161.13
0,1,16:162.13
6,1,16:161.13
-8,2,16:161.13
-7,2,16:162.13
3,2,16:162.13
5,2,16:161.13
9,2,16:161.13
-10,3,16:161.13
-7,3,16:161.13
-6,3,16:161.13
0,3,16:161.13
4,3,16:161.13
6,3,16:161.13
-9,4,16:161.13
-8,4,16:161.13
-1,4,16:162.13
9,4,16:161.13
-10,5,16:161.13
5,5,16:161.13
6,5,16:161.13
8,5,16:161.13
-4,6,16:161.13
-2,6,16:161.13
3,6,16:161.13
7,6,16:161.13
-9,7,16:161.13
-6,7,16:161.13
-3,7,16:161.13
2,7,16:161.13
6,7,16:161.13
7,7,16:161.13
-8,8,16:161.13
3,8,16:161.13
7,8,16:161.13
-1,9,16:161.13
0,9,16:161.13
-3,12,16:161.13
-4,-10,17:161.13
-3,-10,17:161.13
-2,-10,17:161.13
2,-10,17:161.13
4,-10,17:161.13
2,-9,17:161.13
7,-9,17:161.13
-6,-8,17:161.13
-4,-8,17:161.13
3,-8,17:162.13
6,-8,17:161.13
9,-8,17:161.13
-5,-7,17:161.13
-4,-7,17:161.13
-2,-7,17:161.13
3,-7,17:161.13
5,-7,17:161.13
7,-7,17:161.13
-6,-6,17:161.13
-5,-6,17:161.13
0,-6,17:161.13
6,-6,17:161.13
7,-6,17:162.13
10,-6,17:161.13
-8,-5,17:161.13
-7,-5,17:161.13
-1,-5,17:162.13
0,-5,17:161.13
3,-5,17:161.13
6,-5,17:161.13
8,-5,17:161.13
9,-5,17:161.13
-10,-4,17:161.13
-9,-4,17:161.13
-5,-4,17:161.13
-1,-4,17:162.13
5,-4,17:161.13
6,-4,17:162.13
8,-4,17:161.13
-9,-3,17:161.13
-5,-3,17:161.13
-3,-3,17:161.13
-1,-3,17:161.13
6,-3,17:161.13
7,-3,17:161.13
-8,-2,17:162.13
-7,-2,17:161.13
6,-1,17:161.13
-10,0,17:161.13
3,0,17:161.13
5,0,17:161.13
6,0,17:162.13
9,0,17:161.13
-9,1,17:161.13
0,1,17:162.13
8,1,17:161.13
3,2,17:162.13
6,2,17:161.13
7,2,17:161.13
8,2,17:161.13
9,2,17:161.13
-10,3,17:161.13
-8,3,17:162.13
-7,3,17:161.13
-6,3,17:161.13
5,3,17:161.13
6,3,17:161.13
-11,4,17:161.13
-5,4,17:161.13
-1,4,17:162.13
0,4,17:161.13
5,4,17:161.13
6,4,17:161.13
8,4,17:161.13
9,4,17:161.13
-9,5,17:161.13
-7,5,17:161.13
-5,5,17:161.13
-4,5,17:161.13
6,5,17:161.13
-8,6,17:161.13
-3,6,17:161.13
5,6,17:161.13
9,6,17:161.13
-6,7,17:161.13
-5,7,17:161.13
-3,7,17:161.13
-2,7,17:161.13
1,7,17:161.13
-9,8,17:161.13
3,8,17:161.13
4,8,17:161.13
7,8,17:161.13
-6,9,17:161.13
-3,9,17:161.13
-1,9,17:161.13
7,9,17:161.13
-3,12,17:161.13
3,-11,18:161.13
1,-10,18:161.13
3,-10,18:161.13
-4,-9,18:161.13
3,-9,18:161.13
5,-9,18:161.13
6,-9,18:161.13
-5,-8,18:161.13
-2,-8,18:161.13
1,-8,18:161.13
2,-8,18:161.13
3,-8,18:162.13
8,-8,18:161.13
-5,-7,18:161.13
-3,-7,18:161.13
-5,-6,18:161.13
-3,-6,18:161.13
-1,-6,18:162.13
-3,-5,18:161.13
-10,-4,18:161.13
-9,-4,18:161.13
-7,-4,18:161.13
-4,-4,18:161.13
-2,-4,18:162.13
-1,-4,18:161.13
4,-4,18:161.13
6,-4,18:162.13
9,-4,18:161.13
-2,-3,18:161.13
-1,-3,18:161.13
5,-3,18:161.13
-11,-2,18:161.13
-8,-2,18:162.13
-7,-2,18:161.13
-5,-2,18:161.13
8,-2,18:161.5
-9,-1,18:161.13
-7,-1,18:161.13
5,-1,18:161.13
-9,0,18:161.13
-7,0,18:161.13
1,0,18:162.13
7,0,18:161.13
-7,1,18:161.13
3,1,18:161.13
9,1,18:161.13
-1,2,18:162.13
-9,3,18:161.13
-8,3,18:162.13
3,3,18:162.13
6,3,18:161.13
7,3,18:161.13
8,3,18:161.13
9,3,18:161.5
-8,4,18:161.13
-10,5,18:161.13
-6,5,18:161.13
-4,5,18:161.13
-2,5,18:162.13
3,5,18:161.13
6,5,18:161.13
-9,6,18:161.13
-8,6,18:161.13
-5,6,18:161.13
2,6,18:161.13
4,6,18:161.13
7,6,18:161.13
9,6,18:161.13
3,7,18:161.13
7,7,18:161.13
9,7,18:161.5
-8,8,18:161.13
6,8,18:161.13
8,8,18:161.13
-3,9,18:161.13
-3,11,18:161.13
-2,11,18:161.13
2,-11,19:161.13
3,-11,19:161.13
-1,-9,19:161.13
0,-9,19:161.13
2,-9,19:161.13
-2,-8,19:161.13
2,-8,19:161.13
5,-8,19:161.13
6,-8,19:161.13
-6,-7,19:161.13
-5,-7,19:161.13
-1,-7,19:162.13
0,-7,19:161.13
-6,-6,19:161.13
-4,-6,19:161.13
-2,-6,19:161.13
-1,-6,19:161.13
4,-6,19:161.13
-3,-5,19:161.13
9,-5,19:161.13
-6,-4,19:161.13
-2,-4,19:162.13
-1,-4,19:161.13
4,-4,19:161.13
6,-4,19:162.13
7,-4,19:161.13
-12,-3,19:161.13
-11,-3,19:161.13
-9,-3,19:162.13
-3,-3,19:161.13
3,-3,19:161.13
6,-3,19:161.13
-10,-2,19:161.13
-9,-2,19:161.13
-8,-2,19:161.13
-6,-2,19:161.13
-5,-2,19:161.13
6,-2,19:161.13
-6,-1,19:161.13
-5,-1,19:161.13
6,-1,19:161.13
-8,0,19:161.13
1,0,19:162.13
4,0,19:161.13
-8,1,19:161.13
5,1,19:161.13
8,1,19:161.13
-1,2,19:162.13
4,2,19:161.13
5,2,19:161.13
6,2,19:161.13
7,2,19:161.13
-11,3,19:161.13
-8,3,19:162.13
-7,3,19:161.13
3,3,19:162.13
6,3,19:161.13
-11,4,19:161.13
-7,4,19:161.13
-6,4,19:161.13
-5,4,19:161.13
-4,4,19:161.13
3,4,19:161.13
-6,5,19:161.13
-2,5,19:162.13
7,5,19:161.13
8,5,19:161.13
-9,6,19:161.13
-6,6,19:161.13
-1,6,19:161.13
0,6,19:161.13
2,6,19:161.13
3,6,19:161.13
4,6,19:161.13
6,6,19:161.13
-7,7,19:161.13
-4,7,19:161.13
-3,7,19:161.13
1,7,19:161.13
4,7,19:161.13
0,8,19:161.13
-7,9,19:161.13
-6,9,19:161.13
1,9,19:161.13
3,9,19:161.13
6,9,19:161.13
-1,10,19:161.13
0,-10,20:161.13
-2,-9,20:161.13
1,-9,20:161.13
4,-9,20:161.13
-4,-8,20:161.13
-5,-7,20:161.13
-3,-7,20:161.13
-2,-7,20:161.13
-1,-7,20:162.13
2,-7,20:161.13
3,-7,20:161.13
4,-7,20:161.13
5,-7,20:161.13
7,-7,20:161.13
8,-7,20:161.13
-9,-6,20:161.13
-3,-6,20:161.13
-2,-6,20:161.13
7,-6,20:161.13
8,-6,20:161.13
-9,-5,20:161.13
-3,-5,20:161.13
-1,-5,20:161.13
6,-5,20:161.13
-9,-4,20:161.13
-8,-4,20:161.13
-5,-4,20:161.13
-4,-4,20:161.13
-3,-4,20:161.13
-2,-4,20:162.13
-1,-4,20:161.13
0,-4,20:161.13
3,-4,20:161.13
6,-4,20:161.13
-11,-3,20:161.13
-10,-3,20:161.13
-9,-3,20:162.13
-8,-3,20:161.13
-6,-3,20:161.13
6,-3,20:161.13
8,-3,20:161.13
-7,-2,20:161.13
-6,-2,20:161.13
-4,-2,20:161.13
5,-2,20:161.13
7,-2,20:161.13
-11,-1,20:161.13
-6,-1,20:161.13
1,-1,20:162.13
5,-1,20:161.13
6,-1,20:161.13
-10,0,20:161.13
3,0,20:161.13
4,0,20:161.13
5,0,20:161.13
7,0,20:161.13
9,0,20:161.13
3,1,20:161.13
6,1,20:161.13
-10,2,20:161.13
-8,2,20:161.13
-6,2,20:161.13
-1,2,20:162.13
4,2,20:161.13
6,2,20:161.13
-10,3,20:161.13
-7,3,20:161.13
-5,3,20:161.13
3,3,20:162.13
5,3,20:161.13
6,3,20:161.13
-9,4,20:161.13
-8,4,20:161.13
-7,4,20:161.13
1,4,20:161.13
3,4,20:161.13
4,4,20:161.13
-9,5,20:161.13
-6,5,20:161.13
-3,5,20:161.13
1,5,20:161.13
3,5,20:161.13
-5,6,20:161.13
-2,6,20:161.13
-1,6,20:162.13
0,6,20:161.13
6,6,20:161.13
0,7,20:161.13
-6,8,20:161.13
-4,8,20:161.13
-2,8,20:161.13
1,8,20:161.13
3,8,20:161.13
-3,10,20:161.13
2,10,20:161.13
1,11,20:161.13
-2,-8,21:161.13
3,-8,21:161.13
1,-7,21:161.13
-3,-6,21:161.13
-2,-6,21:161.13
-1,-6,21:161.13
7,-6,21:161.13
-9,-5,21:161.13
-2,-5,21:162.13
1,-5,21:161.5
4,-5,21:161.13
8,-5,21:161.5
-10,-4,21:161.13
-7,-4,21:161.13
-6,-4,21:161.13
-5,-4,21:161.13
4,-4,21:161.5
6,-4,21:161.13
-11,-3,21:161.13
-9,-3,21:161.13
-8,-3,21:161.13
-7,-3,21:161.13
1,-3,21:161.13
6,-3,21:161.13
-8,-2,21:161.13
-5,-2,21:161.13
6,-2,21:161.13
1,-1,21:162.13
6,-1,21:161.13
6,0,21:161.13
-7,1,21:161.13
3,1,21:161.13
4,1,21:161.13
-8,2,21:161.13
-5,2,21:161.13
3,2,21:161.13
6,2,21:161.13
7,2,21:161.13
8,2,21:161.13
-8,3,21:161.13
-7,3,21:161.13
-2,3,21:162.13
4,3,21:162.13
6,3,21:161.13
-9,4,21:161.13
-8,4,21:161.13
-4,4,21:161.13
1,4,21:161.13
2,4,21:161.13
3,4,21:161.13
6,4,21:161.13
7,4,21:161.13
-6,5,21:161.13
0,5,21:161.13
5,5,21:161.13
6,5,21:161.13
-7,6,21:161.13
-4,6,21:161.13
-2,6,21:161.13
-1,6,21:162.13
0,6,21:161.13
5,6,21:161.13
-8,7,21:161.13
1,7,21:161.13
2,7,21:161.13
3,7,21:161.13
6,7,21:161.5
-1,8,21:161.13
1,8,21:161.13
2,8,21:161.13
3,10,21:161.5
0,-8,22:161.13
-1,-7,22:161.13
1,-7,22:161.5
-7,-6,22:161.13
-2,-5,22:162.13
-7,-4,22:161.13
-6,-4,22:161.13
-1,-4,22:161.13
6,-4,22:161.13
-10,-3,22:161.13
-9,-3,22:161.13
-8,-3,22:161.13
-7,-3,22:161.13
-6,-3,22:161.13
-1,-3,22:161.13
-7,-2,22:161.13
-6,-2,22:161.13
1,-2,22:162.13
5,-2,22:161.13
6,-2,22:161.13
-6,-1,22:161.13
3,-1,22:161.13
4,-1,22:161.13
5,0,22:161.13
-5,2,22:161.13
3,2,22:161.13
5,2,22:161.13
6,2,22:161.13
-8,3,22:161.13
-4,3,22:161.13
-2,3,22:162.13
4,3,22:162.13
-8,4,22:161.13
-4,4,22:161.13
-3,4,22:161.13
0,4,22:161.13
3,4,22:161.13
6,4,22:161.13
-5,5,22:161.13
-4,5,22:161.13
-3,5,22:161.13
0,5,22:161.13
3,5,22:161.13
5,5,22:161.13
-5,6,22:161.13
-1,6,22:162.13
0,6,22:161.13
2,6,22:161.13
-8,7,22:161.13
-3,7,22:161.13
0,7,22:161.13
1,7,22:161.13
4,7,22:161.13
-3,8,22:161.13
-1,8,22:161.13
1,8,22:161.13
4,8,22:161.13
-1,9,22:161.13
-6,-7,23:161.13
-8,-6,23:161.13
-6,-6,23:161.13
-3,-6,23:161.13
-2,-6,23:161.13
-4,-5,23:161.13
-2,-5,23:162.13
-9,-4,23:161.13
-6,-4,23:161.13
-3,-4,23:161.13
-9,-3,23:161.13
-7,-3,23:161.13
-5,-3,23:161.13
2,-3,23:161.13
-7,-2,23:161.13
-2,-2,23:161.13
1,-2,23:162.13
2,-2,23:161.13
6,-2,23:161.13
4,-1,23:161.13
-8,0,23:161.13
1,0,23:161.13
4,0,23:161.13
5,0,23:161.13
6,0,23:161.13
7,0,23:161.13
7,2,23:161.13
-2,3,23:162.13
1,3,23:161.13
2,3,23:161.13
6,3,23:161.13
-4,4,23:161.13
-1,4,23:161.13
1,4,23:161.13
5,4,23:162.13
7,4,23:161.13
8,4,23:161.13
-4,5,23:161.13
-1,5,23:161.13
0,5,23:161.13
1,5,23:161.13
2,5,23:161.13
4,5,23:161.13
7,5,23:161.13
-8,6,23:161.13
-7,6,23:161.13
-4,6,23:161.13
4,6,23:161.13
-3,7,23:161.13
5,7,23:161.13
3,8,23:161.13
-3,-7,24:161.13
-1,-7,24:161.13
-6,-6,24:161.13
-7,-5,24:161.13
-3,-5,24:162.13
1,-5,24:161.13
-6,-4,24:161.13
-3,-4,24:161.13
1,-4,24:161.13
3,-4,24:161.13
-8,-3,24:161.13
-5,-3,24:161.13
-1,-3,24:161.13
0,-3,24:161.13
1,-3,24:161.13
2,-3,24:161.13
-8,-2,24:161.13
-6,-2,24:161.13
-4,-2,24:161.13
-1,-2,24:161.13
0,-2,24:161.13
1,-2,24:162.13
2,-2,24:161.13
-7,-1,24:161.13
-4,-1,24:161.13
1,-1,24:161.13
7,-1,24:161.5
-6,1,24:161.13
-5,1,24:161.13
1,1,24:161.13
0,2,24:161.13
3,2,24:161.13
-3,3,24:162.13
3,3,24:161.13
5,3,24:161.13
8,3,24:161.13
-1,4,24:162.13
1,4,24:161.13
3,4,24:161.13
4,4,24:161.13
1,5,24:161.13
3,5,24:161.13
4,6,24:161.13
-3,7,24:161.13
-1,7,24:161.13
2,7,24:161.13
5,7,24:161.13
6,7,24:161.5
-6,-8,25:161.13
-5,-8,25:161.13
-1,-7,25:161.13
-9,-6,25:161.13
-8,-6,25:161.13
-7,-6,25:161.13
-9,-5,25:161.13
-3,-5,25:162.13
-8,-4,25:161.13
-6,-3,25:161.13
-5,-3,25:161.13
-4,-3,25:161.13
2,-3,25:162.13
6,-3,25:161.13
-8,-2,25:161.13
-5,-2,25:161.13
0,-2,25:161.13
-7,-1,25:161.13
-2,-1,25:161.13
-1,-1,25:161.13
3,-1,25:161.13
-9,0,25:161.13
-7,0,25:161.13
3,0,25:161.13
4,0,25:161.13
5,0,25:161.13
6,0,25:161.13
-5,1,25:161.13
1,1,25:161.13
3,1,25:161.13
-8,3,25:161.13
-3,3,25:162.13
0,3,25:161.13
5,3,25:161.13
-7,4,25:161.13
-2,4,25:161.13
-1,4,25:162.13
0,4,25:161.13
3,4,25:161.13
-7,5,25:161.13
1,5,25:161.13
5,5,25:161.13
4,6,25:161.13
-1,7,25:161.13
-4,-8,26:161.13
-6,-6,26:161.13
-9,-5,26:161.13
-3,-5,26:162.13
3,-5,26:161.13
4,-5,26:161.13
5,-5,26:161.13
-8,-4,26:161.13
-5,-4,26:161.13
-3,-4,26:161.13
-2,-4,26:161.13
-1,-4,26:161.13
4,-4,26:161.13
5,-4,26:161.13
6,-4,26:161.13
-4,-3,26:161.13
-2,-3,26:161.13
1,-3,26:161.13
2,-3,26:162.13
7,-3,26:161.13
-9,-2,26:161.13
4,-2,26:161.13
7,-2,26:161.5
2,-1,26:161.13
3,0,26:161.13
6,0,26:161.5
-3,1,26:161.13
2,1,26:161.13
4,1,26:161.13
5,1,26:161.13
-8,2,26:161.13
-6,2,26:161.13
-3,2,26:162.13
6,3,26:161.5
-6,4,26:161.13
-3,4,26:161.13
-1,4,26:161.13
0,4,26:162.13
2,4,26:161.13
5,4,26:161.13
2,5,26:161.13
-1,7,26:161.13
-1,-6,27:161.13
-3,-5,27:161.13
-2,-5,27:161.13
1,-5,27:161.13
4,-5,27:161.13
-4,-4,27:161.13
0,-4,27:161.13
0,-3,27:161.13
2,-3,27:162.13
3,-3,27:161.13
4,-3,27:161.13
-4,-2,27:161.13
-3,-2,27:161.13
2,-2,27:161.13
-5,-1,27:161.13
2,-1,27:161.13
3,-1,27:161.13
-8,0,27:161.13
-2,1,27:161.13
-7,2,27:161.13
-6,2,27:161.13
-3,2,27:162.13
5,2,27:161.13
-4,3,27:161.13
-3,3,27:161.13
-2,3,27:161.13
-1,3,27:161.13
1,3,27:161.13
0,4,27:161.13
2,4,27:161.13
0,5,27:161.13
-1,7,27:161.13
-3,-7,28:161.13
-5,-6,28:161.13
1,-6,28:161.13
3,-6,28:161.13
-6,-5,28:161.13
2,-5,28:161.13
4,-5,28:161.13
-6,-4,28:161.13
-2,-4,28:161.13
0,-4,28:161.13
1,-4,28:161.13
-1,-3,28:161.13
2,-3,28:162.13
-8,-1,28:161.13
4,-1,28:161.13
0,0,28:161.13
4,0,28:161.13
-1,1,28:161.13
1,1,28:161.13
2,1,28:161.13
4,1,28:161.13
6,1,28:161.13
-4,2,28:162.13
1,2,28:161.13
-5,3,28:161.13
3,3,28:161.13
-4,4,28:161.13
-2,4,28:161.13
0,4,28:161.13
-3,5,28:161.13
0,5,28:161.13
-1,6,28:161.13
0,6,28:161.13
-4,-5,29:161.13
0,-4,29:161.13
2,-4,29:161.13
3,-4,29:161.13
4,-4,29:161.13
1,-3,29:161.13
2,-3,29:162.13
-1,-2,29:161.13
2,0,29:161.13
3,0,29:161.13
-6,1,29:161.13
1,1,29:161.13
-6,2,29:161.13
-4,2,29:161.13
-3,3,29:161.13
-1,4,29:161.13
0,4,29:161.13
-1,5,29:161.13
0,-5,30:161.13
1,-3,30:161.13
3,-2,30:161.13
5,-2,30:161.5
1,-1,30:161.13
-6,0,30:161.13
-4,0,30:161.13
2,0,30:161.13
3,0,30:161.13
-6,1,30:161.13
4,1,30:161.13
-6,2,30:161.13
-5,2,30:161.13
1,2,30:161.13
4,2,30:161.13
-4,4,30:161.13
2,-3,31:161.13
3,-3,31:161.13
0,-2,31:161.13
1,-1,31:161.13
3,-1,31:161.13
-4,1,31:161.13
2,1,31:161.13
4,1,31:161.5
-4,2,31:161.13
-5,3,31:161.13
-3,3,31:161.5
1,-2,32:161.13
