[META]
version=2.0
spawnOnBlockType=2,3
spawnSunlight=True
spawnDarkness=True
spawnWater=False
spawnLava=False
underFill=False
randomRotation=True
dig=True
tree=True
branch=False
needsFoundation=True
rarity=100
collisionPercentage=20
spawnElevationMin=0
spawnElevationMax=200
spawnInBiome=Custom
[DATA]
0,0,0:162.1
0,0,1:162.1
0,0,2:162.1
-1,-3,3:18.6
1,-3,3:18.14
2,-2,3:18.6
-3,-1,3:18.6
0,-1,3:18.6
2,-1,3:18.6
-3,0,3:18.6
-2,0,3:18.6
0,0,3:162.1
3,0,3:18.6
0,1,3:18.14
1,1,3:18.6
-2,2,3:18.6
2,2,3:18.6
-1,3,3:18.6
0,3,3:18.6
-1,-5,4:18.6
-3,-4,4:18.6
0,-4,4:18.14
1,-4,4:18.14
2,-4,4:18.14
3,-4,4:18.14
-3,-3,4:18.6
1,-3,4:18.14
-2,-2,4:18.6
0,-2,4:18.14
1,-2,4:18.14
-3,-1,4:18.6
-5,0,4:18.6
-4,0,4:18.6
-1,0,4:18.14
0,0,4:162.1
1,0,4:18.14
3,0,4:18.14
5,0,4:18.14
-4,1,4:18.14
-1,1,4:18.14
5,1,4:18.14
0,2,4:18.14
-1,3,4:18.6
4,3,4:18.6
1,4,4:18.6
2,4,4:18.6
0,5,4:18.6
1,5,4:18.6
-1,-5,5:18.6
0,-5,5:18.6
2,-5,5:18.6
-2,-4,5:18.6
-1,-4,5:18.6
1,-4,5:18.6
-4,-3,5:18.6
-1,-3,5:18.6
-5,-2,5:18.6
-2,-2,5:18.6
0,-2,5:18.6
2,-2,5:18.6
2,-1,5:18.6
3,-1,5:18.6
5,-1,5:18.6
-5,0,5:18.6
-3,0,5:18.6
0,0,5:162.1
1,0,5:18.6
5,0,5:18.6
-1,1,5:18.6
0,1,5:18.6
4,2,5:18.6
-4,3,5:18.14
0,3,5:18.6
3,3,5:18.6
0,4,5:18.6
3,4,5:18.6
1,5,5:18.6
-2,-5,6:18.6
0,-5,6:18.6
-3,-4,6:18.6
0,-4,6:18.6
2,-4,6:18.6
-2,-3,6:18.6
-1,-3,6:18.6
2,-3,6:18.6
4,-3,6:18.6
-2,-2,6:18.6
0,-2,6:18.6
4,-2,6:18.6
5,-2,6:18.6
-5,-1,6:18.6
-4,-1,6:18.6
0,-1,6:18.6
1,-1,6:18.6
-5,0,6:18.6
-4,0,6:18.6
-2,0,6:18.6
0,0,6:162.1
1,0,6:18.6
2,0,6:18.6
4,0,6:18.6
5,0,6:18.6
0,1,6:18.6
5,1,6:18.6
0,2,6:18.6
2,2,6:18.6
-4,3,6:18.6
-2,3,6:18.6
0,3,6:18.6
4,3,6:18.6
-3,4,6:18.6
-2,4,6:18.6
0,4,6:18.6
1,4,6:18.6
-2,5,6:18.6
0,5,6:18.6
1,5,6:18.6
2,5,6:18.6
-2,-5,7:18.14
1,-5,7:18.14
2,-5,7:18.14
0,-4,7:18.14
-1,-3,7:18.14
0,-3,7:18.14
1,-3,7:18.14
-4,-2,7:18.14
0,-2,7:18.14
2,-2,7:18.14
-2,-1,7:18.14
-1,-1,7:18.14
0,-1,7:18.14
2,-1,7:18.14
-3,0,7:18.14
-2,0,7:18.14
-1,0,7:18.14
0,0,7:162.1
3,0,7:18.14
4,0,7:18.14
-3,1,7:18.14
0,1,7:18.14
3,1,7:18.14
1,2,7:18.14
2,2,7:18.14
4,2,7:18.14
-4,3,7:18.14
-3,3,7:18.14
-2,3,7:18.14
-1,3,7:18.14
0,3,7:18.14
1,3,7:18.14
2,3,7:18.14
3,3,7:18.14
-1,4,7:18.14
0,4,7:18.14
2,5,7:18.14
-2,-4,8:18.6
-1,-4,8:18.6
1,-4,8:18.6
-2,-2,8:18.6
-1,-2,8:18.6
4,-2,8:18.6
-2,-1,8:18.6
0,-1,8:18.6
4,-1,8:18.6
-4,0,8:18.6
-3,0,8:18.6
-2,0,8:18.6
0,0,8:162.1
3,0,8:18.6
4,0,8:18.6
1,1,8:18.6
-2,2,8:18.6
0,2,8:18.6
2,2,8:18.6
3,2,8:18.6
-3,3,8:18.6
-1,3,8:18.6
1,3,8:18.6
-2,4,8:18.6
0,4,8:18.6
0,-3,9:18.6
1,-3,9:18.6
-1,-2,9:18.6
0,-2,9:18.6
1,-2,9:18.6
2,-2,9:18.6
-3,-1,9:18.6
-1,-1,9:18.6
0,-1,9:18.6
3,-1,9:18.6
-2,0,9:18.6
-1,0,9:18.6
0,0,9:162.1
-2,1,9:18.6
0,1,9:18.6
-1,2,9:18.6
1,2,9:18.6
1,3,9:18.6
2,4,5:162.13
1,4,5:162.13
2,3,5:162.13
0,2,5:162.13
-1,2,5:162.13
-2,2,5:162.13
-3,2,5:162.13
4,1,5:162.13
2,1,5:162.13
-3,1,5:162.13
4,0,5:162.13
3,0,5:162.13
2,0,5:162.13
-1,0,5:162.13
-2,0,5:162.13
-4,0,5:162.13
0,-1,5:162.13
-1,-1,5:162.13
-3,-1,5:162.13
3,-2,5:162.13
3,-3,5:162.13
2,-3,5:162.13
0,-3,5:162.13
-2,-3,5:162.13
2,-4,5:162.13
0,4,4:162.13
-1,4,4:162.13
0,3,4:162.13
2,2,4:162.13
1,2,4:162.13
-2,2,4:162.13
3,1,4:162.13
0,1,4:162.13
4,0,4:162.13
2,0,4:162.13
-2,0,4:162.13
-3,0,4:162.13
1,-1,4:162.13
0,-1,4:162.13
-2,-1,4:162.13
-4,-1,4:162.13
3,-2,4:162.13
2,-2,4:162.13
-1,-2,4:162.13
-3,-2,4:162.13
-2,-4,4:162.13
0,2,3:162.13
-1,2,3:162.13
2,1,3:162.13
-2,1,3:162.13
2,0,3:162.13
-1,0,3:162.13
1,-1,3:162.13
-1,-1,3:162.13
1,-2,3:162.13
-2,-2,3:162.13
0,-3,3:162.13
