[META]
version=2.0
spawnOnBlockType=2,3
spawnSunlight=True
spawnDarkness=True
spawnWater=False
spawnLava=False
underFill=False
randomRotation=True
dig=True
tree=True
branch=False
needsFoundation=True
rarity=100
collisionPercentage=20
spawnElevationMin=0
spawnElevationMax=200
spawnInBiome=Custom
[DATA]
0,0,0:162.1
0,0,1:162.1
-2,-2,2:18.14
0,-2,2:18.14
1,-2,2:18.14
-3,-1,2:18.14
-1,-1,2:18.14
-1,0,2:18.14
0,0,2:162.1
2,0,2:18.14
0,1,2:18.14
-2,2,2:18.14
-1,2,2:18.14
1,2,2:18.14
2,2,2:18.14
-2,3,2:18.14
0,3,2:18.14
2,3,2:18.14
-1,-3,3:18.14
-1,-2,3:18.14
1,-2,3:18.14
2,-2,3:18.14
-1,-1,3:18.14
0,-1,3:18.14
2,-1,3:18.14
-2,0,3:18.14
0,0,3:162.1
1,0,3:18.14
2,0,3:18.14
3,0,3:18.14
-3,1,3:18.14
-1,1,3:18.14
0,1,3:18.14
1,1,3:18.14
2,1,3:18.14
-2,2,3:18.14
-1,2,3:18.14
0,2,3:18.14
-1,3,3:18.14
0,3,3:18.14
1,3,3:18.14
0,-2,4:18.14
2,-1,4:18.14
-2,0,4:18.14
0,0,4:18.14
1,0,4:18.14
2,0,4:18.14
-2,1,4:18.14
-1,1,4:18.14
0,1,4:18.14
2,1,4:18.14
-1,2,4:18.14
0,2,4:18.14
0,2,2:162.13
2,1,2:162.13
1,1,2:162.13
1,0,2:162.13
-2,0,2:162.13
1,-1,2:162.13
0,-1,2:162.13
-2,-1,2:162.13
-1,-2,2:162.13
